Workbook
Name 书籍: collect_type!$H$394

Sheet _config_
A1: 配置表
A3: 表名 | B3: 生成文件名 | C3: 是否输出 | D3: id重复 | E3: 是否是多语言 | F3: 关联 | G3: 列1
A4: card_type | B4: =表3[[#This Row],[表名]]&".json" -> card_type.json | C4: YES | D4: NO | E4: NO | F4: 卡牌类型表
A5: card | B5: =表3[[#This Row],[表名]]&".json" -> card.json | C5: YES | D5: NO | E5: NO | F5: 卡牌表
A6: skill | B6: =表3[[#This Row],[表名]]&".json" -> skill.json | C6: YES | D6: NO | E6: NO | F6: 技能表
A7: buff | B7: =表3[[#This Row],[表名]]&".json" -> buff.json | C7: YES | D7: NO | E7: NO | F7: 状态表
A8: passive_type | B8: =表3[[#This Row],[表名]]&".json" -> passive_type.json | C8: YES | D8: NO | E8: NO | F8: 心法类型
A9: passive | B9: =表3[[#This Row],[表名]]&".json" -> passive.json | C9: YES | D9: NO | E9: NO | F9: 心法表
A10: battle_group | B10: =表3[[#This Row],[表名]]&".json" -> battle_group.json | C10: YES | D10: NO | E10: NO | F10: 战斗卡牌表
A11: monster | B11: =表3[[#This Row],[表名]]&".json" -> monster.json | C11: YES | D11: NO | E11: NO | F11: 怪物表
A12: drop | B12: =表3[[#This Row],[表名]]&".json" -> drop.json | C12: YES | D12: NO | E12: NO | F12: 掉落表
A13: property_exp | B13: =表3[[#This Row],[表名]]&".json" -> property_exp.json | C13: YES | D13: NO | E13: NO | F13: 五种属性升级所需要的经验值
A14: home_shop | B14: =表3[[#This Row],[表名]]&".json" -> home_shop.json | C14: YES | D14: NO | E14: NO | F14: 丹药商品表
A15: home_decorate | B15: =表3[[#This Row],[表名]]&".json" -> home_decorate.json | C15: YES | D15: NO | E15: NO | F15: 房屋装饰表
... A25: home_decorate_level | B25: =表3[[#This Row],[表名]]&".json" -> home_decorate_level.json | C25: YES | D25: NO | E25: NO | F25: 建筑等级加成表

Sheet _table_
A1: 字段解析法
A2: 编号 | B2: 标题 | C2: 作用名 | D2: 中文解释 | E2: 字段 | F2: 字段类型 | G2: 数字定义
A3: id | B3: table_name | C3: name | D3: field_name | E3: field | F3: type
A4: 101 | B4: 道具信息 | C4: goods_info | D4: 物品id | E4: goods_id | F4: int | I4: TAB:[goods_info]
A5: 101 | B5: 道具信息 | C5: goods_info | D5: 物品数量 | E5: goods_num | F5: int | I5: TAB:[goods_info]
I6: TAB:[cross_event]
I7: TAB:[cross_event]
I8: TAB:[chapter_box]
I9: TAB:[chapter_box]
I10: TAB:[clear_reward]
I11: TAB:[clear_reward]
I12: TAB:[data_map]
I13: TAB:[data_map]
I14: TAB:[hang_up_time_range]
I15: TAB:[hang_up_time_range]
I16: TAB:[hang_up_time_range]
I17: TAB:[step_drop]

Sheet _language_
A1: 语言表
A2: 编号 | B2: 编码格式 | C2: 语言
A3: 1 | B3: [cn] | C3: 中文

Sheet table符号定义
A1: table表符号定义
A2: 符号 | B2: 作用
A3: | | B3: 第一层字段连接符 | D3: 第1层
A4: ； | B4: 第二层并列连接符 | D4: 第2层
A5: # | B5: 第三层并列连接符 | D5: 第3层
A6: $ | B6: 第四层并列连接符 | D6: 第4层

Sheet sound_effect
A1: 音效配置表 | B1: 对应位置
A2: id | C2: 音效资源 | D2: 是否循环1循环0不循环 | E2: 循环间隔（毫秒） | F2: 音量（万分比） | G2: 是否为背景音乐 | H2: 延迟播放（毫秒）
A3: INT | C3: STRING | D3: INT | E3: INT | F3: INT | G3: INT | H3: INT
A4: id | C4: resource | D4: repeat | E4: step | F4: volume | G4: is_BGM | H4: delay
A6: 1 | B6: 创建角色界面 | C6: lilianBGM | D6: 1 | E6: 2500 | F6: 9000 | G6: 1
A7: 2 | B7: 按键音（通用点击） | C7: click | D7: 0 | F7: 10000
A8: 3 | B8: 按键音返回 | C8: back | D8: 0 | F8: 10000
A9: 4 | B9: 种田背景音 | C9: qian | D9: 0 | E9: 2500 | F9: 10000 | G9: 0
A10: 5 | B10: 战斗背景音1 | C10: bgm_battle | D10: 1 | E10: 2500 | F10: 7000 | G10: 1 | I10: 进入战斗后，随机展示一种音效
A11: 6 | B11: 战斗背景音2 | C11: bgm_battle | D11: 1 | E11: 2500 | F11: 10000 | G11: 1
A12: 7 | B12: 金属性音效 | C12: matal | D12: 0 | F12: 10000 | K12: 1
A13: 8 | B13: 木属性音效 | C13: wood | D13: 0 | F13: 10000 | K13: 2
A14: 9 | B14: 水属性音效 | C14: water | D14: 0 | F14: 10000 | H14: 200 | K14: 3
A15: 10 | B15: 火属性音效 | C15: fire | D15: 0 | F15: 10000 | K15: 4
A16: 11 | B16: 土属性音效 | C16: soil | D16: 0 | F16: 10000 | K16: 5
A17: 12 | B17: 锻炼发力1 | C17: hit1 | D17: 1 | F17: 10000 | I17: 连脚踢 | J17: 击打类锻炼，可以用脚踢。御剑类用hit2.
A18: 13 | B18: 锻炼发力1 | C18: hit2 | D18: 1 | F18: 10000 | I18: 一击
A19: 14 | B19: 砍柴 | C19: cut_wood | D19: 1 | F19: 10000
A20: 15 | B20: buff生成音效 | C20: buff_create | D20: 0 | F20: 10000
A21: 16 | B21: 回复技能 | C21: recover | D21: 0 | F21: 10000
A22: 17 | B22: 鬼魂技能 | C22: demo | D22: 0 | F22: 10000
A23: 18 | B23: 中毒技能 | C23: poison | D23: 0 | F23: 10000
A24: 19 | B24: 火焰音效2 | C24: fire1 | D24: 0 | F24: 10000 | H24: 250
A25: 20 | B25: 拳法特效 | C25: quanfa | D25: 0 | F25: 10000 | H25: 400
A26: 21 | B26: 冰冻技能 | C26: ice | D26: 0 | F26: 10000 | H26: 350
A27: 22 | B27: 护盾1 | C27: hudun | D27: 0 | F27: 10000
A28: 23 | B28: 护盾2 | C28: hudun1 | D28: 0 | F28: 10000
A29: 24 | B29: 护盾3 | C29: hudun2 | D29: 0 | F29: 10000
A30: 25 | B30: 选择卡牌音效 | C30: choose | D30: 0 | F30: 10000
A31: 26 | B31: 电流 | C31: dianliu | D31: 0 | F31: 10000
A32: 27 | B32: 多段伤害 | C32: duoduanshanghai | D32: 0 | F32: 10000
A33: 28 | B33: 浪 | C33: wave | D33: 0 | F33: 10000 | H33: 400
A34: 29 | B34: 大雷击 | C34: electric_current_big | D34: 0 | F34: 10000
A35: 30 | B35: 小雷击 | C35: electric_current | D35: 0 | F35: 10000
A36: 31 | B36: 剑 | C36: normal_weapon | D36: 0 | F36: 10000
A37: 32 | B37: 暗器 | C37: anqi | D37: 0 | F37: 10000
A38: 33 | B38: 诅咒 | C38: zuzhou | D38: 0 | F38: 10000
A39: 34 | B39: 多段伤害1 | C39: duoduanshanghai1 | D39: 0 | F39: 10000
A40: 35 | B40: 遇妖怪1低沉 | C40: GhostMoan01 | D40: 0 | F40: 10000
A41: 36 | B41: 遇妖怪2空旷鬼 | C41: GhostMoan02 | D41: 0 | F41: 10000
...

Sheet effect
A1: 特效表
A2: ID | B2: 技能名称 | D2: 资源路径 | E2: 缩放比例（默认是1） | F2: 透明度（默认1） | G2: 特效播放是否循环（0表示不循环） | H2: 飞行类型 0.直接在目标身上层 1.随机角度 2.直线飞行 3.作用在目标下层 4.随机角度多段伤害 | I2: 特效偏移x | J2: 特效偏移y | K2: 五行属性流光 | L2: 五行属性受击 | M2: 卡牌品质 | N2: 特效
A3: INT | B3: STRING | D3: STRING | E3: FLOAT | F3: INT | G3: INT | H3: INT | I3: INT | J3: INT
A4: ID | B4: name | D4: effect_path | E4: size | F4: transparency | G4: if_loop | H4: fly_type | I4: offset_x | J4: offset_y
A6: 1 | B6: 赤炎斩 | D6: chiyanzhan | E6: 1 | F6: 1 | G6: 0 | I6: 0 | J6: 100 | L6: 4 | M6: 1 | N6: kpsx_pt | O6: sy_tongyong
A7: 2 | B7: 御剑诀 | C7: 上层 | D7: yujianshu | E7: 1 | F7: 1 | G7: 0 | I7: 0 | J7: 100 | M7: 2 | N7: kpsx_pt | O7: sy_tongyong
A8: 3 | B8: 火蛇术 | D8: huosheshu_shifa | E8: 1 | F8: 1 | G8: 0 | I8: 0 | J8: 0 | M8: 3 | N8: kpsx_zise | O8: sy_zise
A9: 4 | B9: 石破天惊拳_dd | D9: sptjq_dd | E9: 1 | F9: 1 | G9: 1 | H9: 2 | I9: 0 | J9: 0 | M9: 4 | N9: kpsx_huangse | O9: sy_huangse
A10: 5 | B10: 燃魂拳 | C10: 受击 | D10: shipojingtianquan_sj | E10: 1 | F10: 1 | G10: 0 | H10: 2 | I10: 0 | J10: 0
A11: 6 | B11: 招雷术 | D11: zhaoleishu | E11: 1 | F11: 1 | G11: 0 | I11: 0 | J11: 0
A12: 7 | B12: 吸魂术_difan | D12: xihunshu_difan | E12: 1 | F12: 1 | G12: 0 | I12: 0 | J12: 0
A13: 8 | B13: 吸魂术_zishen | D13: xihunshu_zishen | E13: 1 | F13: 1 | G13: 0 | I13: 0 | J13: 0
A14: 9 | B14: 业火 | D14: xinhuo | E14: 1 | F14: 1 | G14: 0 | I14: 0 | J14: 150
A15: 10 | B15: 水镜 | D15: shuijin | E15: 1 | F15: 1 | G15: 0 | I15: 0 | J15: 0
A16: 11 | B16: 少一张卡（卡牌消失） | D16: kapaixiaoshi | E16: 1 | F16: 1 | G16: 0 | I16: 0 | J16: 0
A17: 12 | B17: 通用受伤 | D17: tongyongshouji | E17: 1 | F17: 1 | G17: 0 | I17: 0 | J17: 0 | L17: 6
A18: 13 | B18: 白色流光 | D18: liuguan_wu_xunhun | E18: 1 | F18: 1 | G18: 0 | H18: 1 | I18: 0 | J18: 0 | K18: 6
A19: 14 | B19: 火焰流光_xunhuan | D19: liuguan_huo_xunhuan | E19: 1 | F19: 1 | G19: 0 | H19: 1 | I19: 0 | J19: 0 | K19: 4
A20: 15 | B20: 金流光_xunhuan | D20: liuguan_jin_xunhuan | E20: 1 | F20: 1 | G20: 0 | H20: 1 | I20: 0 | J20: 0 | K20: 1
A21: 16 | B21: 木流光_xunhuan | D21: liuguan_mu_xunhuan | E21: 1 | F21: 1 | G21: 0 | H21: 1 | I21: 0 | J21: 0 | K21: 2
A22: 17 | B22: 水流光_xunhuan | D22: liuguan_shui_xunhuan | E22: 1 | F22: 1 | G22: 0 | H22: 1 | I22: 0 | J22: 0 | K22: 3
A23: 18 | B23: 土流光_xunhuan | D23: liuguan_tu_xunhuan | E23: 1 | F23: 1 | G23: 0 | H23: 1 | I23: 0 | J23: 0 | K23: 5
A24: 19 | B24: 御剑下层 | D24: yujian_hongse_xiaceng | E24: 1 | F24: 1 | G24: 0 | H24: 3 | I24: 0 | J24: 0
A25: 20 | B25: 卡牌爆炸大 | D25: kapaibijiao_shu | E25: 1 | F25: 1 | G25: 0 | I25: 0 | J25: 0
A26: 21 | B26: 凌霜剑——剑 | D26: linshuangjian_jian | E26: 1 | F26: 1 | G26: 0 | H26: 2 | I26: 0 | J26: 0
A27: 22 | B27: 凌霜剑 | D27: linshuangjian_sj | E27: 1 | F27: 1 | G27: 0 | I27: 0 | J27: 0
A28: 24 | B28: 剑光分化_剑 | D28: JianGuangFenHuaDanDao | E28: 1 | F28: 1 | G28: 0 | H28: 2 | I28: 0 | J28: 0
A29: 25 | B29: 剑光分化 | D29: JianGuangFenHuaHit | E29: 1 | F29: 1 | G29: 0 | I29: 0 | J29: 0
A30: 26 | B30: 剑气侵袭 | D30: JianQiQingXi | E30: 1 | F30: 1 | G30: 0 | I30: 0 | J30: 0
A31: 27 | B31: 剑气雷音——剑 | D31: jianqileiyin_jian | E31: 1 | F31: 1 | G31: 0 | H31: 2 | I31: 0 | J31: 0
A32: 28 | B32: 雷音剑 | D32: jianqileiyin_sj | E32: 1 | F32: 1 | G32: 0 | I32: 0 | J32: 0
A33: 29 | B33: 竹影青烟剑 | D33: zhuyingqingyanjian | E33: 1 | F33: 1 | G33: 0 | H33: 2 | I33: 0 | J33: 0
A34: 30 | B34: 青莲剑歌 | D34: qinglianjiange | E34: 1 | F34: 1 | G34: 0 | I34: 0 | J34: 0
A35: 31 | B35: 撼岳式 | D35: hanyueshi | E35: 1 | F35: 1 | G35: 0 | I35: 0 | J35: 0
A36: 32 | B36: 乱花飞雪 | D36: luanhuafeixue | E36: 1 | F36: 1 | G36: 0 | I36: 0 | J36: 0
A37: 33 | B37: 寒雨千落 | D37: hanyuqianluo | E37: 1 | F37: 1 | G37: 0 | I37: 0 | J37: 0
A38: 34 | B38: 揉身劲 | D38: roushenjin | E38: 1 | F38: 1 | G38: 0 | I38: 0 | J38: 0
A39: 35 | B39: 太玄燕返 | D39: TaiXuanFanYan | E39: 1 | F39: 1 | G39: 0 | I39: 0 | J39: 0
A40: 36 | B40: 飞雪急骤 | D40: feixuejizhou | E40: 1 | F40: 1 | G40: 0 | I40: 0 | J40: 0
A41: 37 | B41: 绝对零度 | D41: beimingbingpo | E41: 1 | F41: 1 | G41: 0 | I41: 0 | J41: 0
...

Sheet card_type
A1: 卡牌类型表 | V1: | | W1: ; | X1: 400023
A2: ID | B2: 技能名称 | D2: 是否可显示 0否 1是 | E2: 卡牌解锁境界小 | F2: 卡牌境界大(锻体炼气也算大境界) | G2: 品质 =1，绿 =2，蓝 =3，紫 =4，橙 =5，红 | H2: 武器属性 =1，拳法 =2，剑法 =3，法术 =4，无 | I2: 五行属性 =1，金 =2，木 =3，水 =4，火 =5，土 =6，无属性 | J2: 最大等级 | K2: 序号（删改可能会导致数据出错） | L2: 动作表现 | M2: 流光特效 | N2: 伤害类型 | O2: 受击特效目标 1自己 2敌方 3双方 | P2: 受击特效上层 | R2: 受击特效下层 | S2: 怪物动作 | T2: 获得练功类型 =1，获得道具 =2，获得功法碎片 | U2: 是否可以使用万能碎片进行升级 0=否 1=是 | V2: 解锁道具id|数量| | W2: 物品 | X2: 数量 | Z2: 调用音效 | AA2: 技能图标 | AB2: 描述,支持X1|X2|X3|代入到描述中,具索引param | AC2: 描述,支持X1|X2|X3|代入到描述中,具索引param | AD2: 技能解锁类型 0.默认解锁 1.心法突破解锁 2.获得物品解锁 | AE2: 客户端获得途径描述 | AF2: 艺术字 | AG2: <span color='#10b847'>[0]</span>
A3: INT | B3: STRING | D3: INT | E3: INT | G3: INT | H3: INT | I3: INT | J3: INT | L3: STRING | M3: INT | O3: INT | P3: INT | R3: INT | S3: INT | T3: INT | U3: INT | V3: STRING | Z3: INT | AA3: STRING | AB3: STRING | AC3: STRING | AD3: INT | AE3: STRING | AF3: STRING
A4: ID | B4: name | D4: if_show | E4: level | G4: quality | H4: weapon | I4: element | J4: max_lev | L4: action_type | M4: light_effect | O4: effect_target | P4: hit_effect_up | R4: hit_effect_down | S4: action_type1 | T4: get_type | U4: if_common_cost | V4: unlock_cost | Z4: sound_effect | AA4: icon | AB4: des1 | AC4: des2 | AD4: unlock_type | AE4: des3 | AF4: art_word
A5: ID | E5: level | G5: quality | H5: weapon | I5: element | J5: max_lev | T5: get_type | U5: if_common_cost | V5: unlock_cost | AD5: unlock_type
A6: 1001 | B6: 红玉指 | C6: 造成%d点%s拳法伤害 | D6: 1 | E6: 1000 | F6: 1 | G6: 1 | H6: 1 | I6: 6 | J6: 30 | K6: =IF(H6=H5,K5+1,1) -> 1 | L6: 2|5| | M6: =P6+1 -> 111 | N6: 1 | O6: 2 | P6: =Q6 -> 110 | Q6: =OFFSET(effect!$A$1,MATCH(B6,effect!B:B,0)-1,0) -> 110 | S6: 10 | T6: 1 | U6: 1 | V6: =W6&$V$1&X6&$V$1&$W$1&$X$1&$V$1&Y6&$V$1&$W$1 -> 301001|10|;400023|500|; | W6: =300000+A6 -> 301001 | X6: 10 | Y6: 500 | Z6: 20 | AA6: icon_05 | AB6: ·达到<span color='#ee6738'>锻体期</span>可通流派选择获得<br/>·通过<span color='#ee6738'>悟道台</span>获取碎片进行领悟获得 | AC6: 红玉指调整浑身气血汇聚指尖一点，犹如红玉，威力不俗，但你若是想用它来对付修仙者，就得小心了。 | AD6: 2 | AE6: <span color='#ee6738'>境界突破</span>时领悟获得" | AF6: wenzi_img_01 | AG6: 负重带
A7: 1002 | B7: 白龙掌 | C7: 造成%d点%s拳法伤害 | D7: 1 | E7: 1000 | F7: 1 | G7: 1 | H7: 1 | I7: 6 | J7: 30 | K7: =IF(H7=H6,K6+1,1) -> 2 | L7: 2|5| | M7: =effect!A93 -> 92 | N7: 1 | O7: 2 | P7: =Q7 -> 91 | Q7: =OFFSET(effect!$A$1,MATCH(B7,effect!B:B,0)-1,0) -> 91 | S7: 10 | T7: 1 | U7: 1 | V7: =W7&$V$1&X7&$V$1&$W$1&$X$1&$V$1&Y7&$V$1&$W$1 -> 301002|10|;400023|500|; | W7: =300000+A7 -> 301002 | X7: 10 | Y7: 500 | Z7: 11 | AA7: icon_02 | AB7: ·达到<span color='#ee6738'>锻体期</span>可通流派选择获得<br/>·通过<span color='#ee6738'>悟道台</span>获取碎片进行领悟获得 | AC7: 白龙掌十分考验根骨力量，有灵力之人使用时气势奔腾，幻化出一条飞天白龙。 | AD7: 2 | AE7: <span color='#ee6738'>境界突破</span>时领悟获得" | AF7: wenzi_img_02 | AG7: 草人桩
A8: 1003 | B8: 风罩拳 | C8: 造成%d点%s拳法伤害，上一招为拳法时，增加造成伤害30%的护甲 | D8: 1 | E8: 1000 | F8: 1 | G8: 1 | H8: 1 | I8: 6 | J8: 30 | K8: =IF(H8=H7,K7+1,1) -> 3 | L8: 2|5| | M8: =effect!A89 -> 88 | N8: 1 | O8: 2 | P8: 12 | Q8: =OFFSET(effect!$A$1,MATCH(B8,effect!B:B,0)-1,0) -> #N/A | S8: 10 | T8: 1 | U8: 1 | V8: =W8&$V$1&X8&$V$1&$W$1&$X$1&$V$1&Y8&$V$1&$W$1 -> 301003|10|;400023|500|; | W8: =300000+A8 -> 301003 | X8: 10 | Y8: 500 | Z8: 20 | AA8: icon_01 | AB8: ·达到<span color='#ee6738'>锻体期</span>可通流派选择获得<br/>·通过<span color='#ee6738'>悟道台</span>获取碎片进行领悟获得 | AC8: 传闻凡俗中曾有人尝以肉身之驱，硬撼熊妖而不死，从而创下了风罩拳这一威猛招式。 | AD8: 2 | AE8: <span color='#ee6738'>境界突破</span>时领悟获得" | AF8: wenzi_img_03 | AG8: 石锁
A9: 1004 | B9: 无痕脚 | C9: 造成%d点%s拳法伤害，本回合每出一张拳法牌，伤害增加25% | D9: 1 | E9: 1000 | F9: 1 | G9: 2 | H9: 1 | I9: 6 | J9: 30 | K9: =IF(H9=H8,K8+1,1) -> 4 | L9: 4|3| | N9: 1 | O9: 2 | P9: =Q9 -> 106 | Q9: =OFFSET(effect!$A$1,MATCH(B9,effect!B:B,0)-1,0) -> 106 | S9: 10 | T9: 1 | U9: 1 | V9: =W9&$V$1&X9&$V$1&$W$1&$X$1&$V$1&Y9&$V$1&$W$1 -> 301004|10|;400023|750|; | W9: =300000+A9 -> 301004 | X9: 10 | Y9: 750 | Z9: 20 | AA9: icon_04 | AB9: ·达到<span color='#ee6738'>锻体期</span>可通流派选择获得<br/>·通过<span color='#ee6738'>悟道台</span>获取碎片进行领悟获得 | AC9: 无痕脚是凡俗世界失传已久的绝技，如果使用恰当，它甚至能将修仙者也踢得伏地不起，痛哭流涕。 | AD9: 2 | AE9: <span color='#ee6738'>境界突破</span>时领悟获得" | AF9: wenzi_img_04 | AG9: 柴堆
A10: 1005 | B10: 青冥指 | C10: 造成%d点%s拳法伤害，上一招为拳法时，增加30%伤害 | D10: 1 | E10: 1000 | F10: 1 | G10: 2 | H10: 1 | I10: 6 | J10: 30 | K10: =IF(H10=H9,K9+1,1) -> 5 | L10: 3|6| | M10: =P10+1 -> 115 | N10: 1 | O10: 2 | P10: =Q10 -> 114 | Q10: =OFFSET(effect!$A$1,MATCH(B10,effect!B:B,0)-1,0) -> 114 | S10: 10 | T10: 1 | U10: 1 | V10: =W10&$V$1&X10&$V$1&$W$1&$X$1&$V$1&Y10&$V$1&$W$1 -> 301005|10|;400023|750|; | W10: =300000+A10 -> 301005 | X10: 10 | Y10: 750 | Z10: 20 | AA10: icon_22 | AB10: ·达到<span color='#ee6738'>锻体期</span>可通境界突破领悟获得<br/>·通过<span color='#ee6738'>悟道台</span>获取碎片进行领悟获得 | AC10: 青冥指是轻衣盟招术，狠辣无比，威力不俗。 | AD10: 2 | AE10: <span color='#ee6738'>境界突破</span>时领悟获得" | AF10: wenzi_img_07
A11: 1006 | B11: 太玄云手 | C11: 造成%d点%s拳法伤害，上一招为拳法时，增加造成伤害30%的护甲 | D11: 1 | E11: 1003 | F11: 1 | G11: 1 | H11: 1 | I11: 6 | J11: 30 | K11: =IF(H11=H10,K10+1,1) -> 6 | L11: 2|5| | M11: =P11+1 -> 105 | N11: 1 | O11: 2 | P11: =Q11 -> 104 | Q11: =OFFSET(effect!$A$1,MATCH(B11,effect!B:B,0)-1,0) -> 104 | S11: 10 | T11: 1 | U11: 1 | V11: =W11&$V$1&X11&$V$1&$W$1&$X$1&$V$1&Y11&$V$1&$W$1 -> 301006|10|;400023|500|; | W11: =300000+A11 -> 301006 | X11: 10 | Y11: 500 | Z11: 20 | AA11: icon_23 | AB11: ·达到<span color='#ee6738'>炼气期</span>可通过境界突破领悟获得<br/>·通过<span color='#ee6738'>悟道台</span>获取碎片进行领悟获得 | AC11: 太玄云手，衔接拳法，借力打力。传闻曾流入凡俗，演化为武林之中的太极拳。 | AD11: 2 | AE11: <span color='#ee6738'>境界突破</span>时领悟获得" | AF11: wenzi_img_08
A12: 1007 | B12: 太玄真罡 | C12: 造成%d点%s拳法伤害，额外造成当前护甲100%的伤害 | D12: 1 | E12: 1003 | F12: 1 | G12: 2 | H12: 1 | I12: 6 | J12: 30 | K12: =IF(H12=H11,K11+1,1) -> 7 | L12: 2|5| | M12: =IF(N12=1,OFFSET(effect!$A$1,MATCH(I12,effect!K:K,0)-1,0),0) -> 13 | N12: 1 | O12: 2 | P12: =Q12 -> 60 | Q12: =OFFSET(effect!$A$1,MATCH(B12,effect!B:B,0)-1,0) -> 60 | S12: 10 | T12: 1 | U12: 1 | V12: =W12&$V$1&X12&$V$1&$W$1&$X$1&$V$1&Y12&$V$1&$W$1 -> 301007|10|;400023|750|; | W12: =300000+A12 -> 301007 | X12: 10 | Y12: 750 | Z12: 20 | AA12: icon_30 | AB12: ·达到<span color='#ee6738'>炼气期</span>可通过境界突破领悟获得<br/>·通过<span color='#ee6738'>悟道台</span>获取碎片进行领悟获得 | AC12: 太玄真罡，以太玄门的运力法门，御四肢百骸之劲力。如天上落陨石，势大且极重。 | AD12: 2 | AE12: <span color='#ee6738'>境界突破</span>时领悟获得" | AF12: wenzi_img_09
A13: 1008 | B13: 恶血爪 | C13: 造成%d点%s拳法伤害，血量低于50%时，获得30%吸血效果 | D13: 1 | E13: 1003 | F13: 1 | G13: 2 | H13: 1 | I13: 4 | J13: 30 | K13: =IF(H13=H12,K12+1,1) -> 8 | L13: 2|5| | M13: =IF(N13=1,OFFSET(effect!$A$1,MATCH(I13,effect!K:K,0)-1,0),0) -> 14 | N13: 1 | O13: 2 | P13: =Q13 -> 79 | Q13: =OFFSET(effect!$A$1,MATCH(B13,effect!B:B,0)-1,0) -> 79 | S13: 10 | T13: 1 | U13: 1 | V13: =W13&$V$1&X13&$V$1&$W$1&$X$1&$V$1&Y13&$V$1&$W$1 -> 301008|10|;400023|750|; | W13: =300000+A13 -> 301008 | X13: 10 | Y13: 750 | Z13: 20 | AA13: icon_99 | AB13: ·达到<span color='#ee6738'>炼气期</span>可通过境界突破领悟获得<br/>·通过<span color='#ee6738'>悟道台</span>获取碎片进行领悟获得 | AC13: 恶血爪是血魔宫招术，当自己受重伤时，可以吸取掠夺敌人的血液。此招术深受广大邪修欢迎。 | AD13: 2 | AE13: <span color='#ee6738'>境界突破</span>时领悟获得" | AF13: wenzi_img_10
A14: 1009 | B14: 炼狱爪 | C14: 造成%d点%s拳法伤害，血量低于50%时，伤害增加30% | D14: 1 | E14: 1003 | F14: 1 | G14: 1 | H14: 1 | I14: 4 | J14: 30 | K14: =IF(H14=H13,K13+1,1) -> 9 | L14: 3|6| | M14: =IF(N14=1,OFFSET(effect!$A$1,MATCH(I14,effect!K:K,0)-1,0),0) -> 14 | N14: 1 | O14: 2 | P14: 79 | Q14: =OFFSET(effect!$A$1,MATCH(B14,effect!B:B,0)-1,0) -> #N/A | S14: 10 | T14: 1 | U14: 1 | V14: =W14&$V$1&X14&$V$1&$W$1&$X$1&$V$1&Y14&$V$1&$W$1 -> 301009|10|;400023|500|; | W14: =300000+A14 -> 301009 | X14: 10 | Y14: 500 | Z14: 20 | AA14: icon_100 | AB14: ·达到<span color='#ee6738'>炼气期</span>可通过境界突破领悟获得<br/>·通过<span color='#ee6738'>悟道台</span>获取碎片进行领悟获得 | AC14: 炼狱爪是噬魂宗长老的成名招术，灵气汇聚，击中敌人肉体时，还会动摇敌人心智魂魄。 | AD14: 2 | AE14: <span color='#ee6738'>境界突破</span>时领悟获得" | AF14: wenzi_img_11
A15: 1010 | B15: 太玄燕返 | C15: 造成%d点%s拳法伤害，本回合每出一张拳法牌，伤害增加30% | D15: 1 | E15: 1003 | F15: 1 | G15: 3 | H15: 1 | I15: 6 | J15: 30 | K15: =IF(H15=H14,K14+1,1) -> 10 | L15: 2|5| | M15: =IF(N15=1,OFFSET(effect!$A$1,MATCH(I15,effect!K:K,0)-1,0),0) -> 13 | N15: 1 | O15: 2 | P15: =Q15 -> 35 | Q15: =OFFSET(effect!$A$1,MATCH(B15,effect!B:B,0)-1,0) -> 35 | S15: 10 | T15: 1 | U15: 1 | V15: =W15&$V$1&X15&$V$1&$W$1&$X$1&$V$1&Y15&$V$1&$W$1 -> 301010|10|;400023|1000|; | W15: =300000+A15 -> 301010 | X15: 10 | Y15: 1000 | Z15: 20 | AA15: icon_24 | AB15: ·达到<span color='#ee6738'>炼气期</span>可通过境界突破领悟获得<br/>·通过<span color='#ee6738'>悟道台</span>获取碎片进行领悟获得 | AC15: 太玄燕返，泥丸宫中演大道，将所有拳式重演后，终结收式。 | AD15: 2 | AE15: <span color='#ee6738'>境界突破</span>时领悟获得" | AF15: wenzi_img_12
A16: 1011 | B16: 揉身劲 | C16: 下1招伤害增加100% | D16: 1 | E16: 1003 | F16: 2 | G16: 1 | H16: 1 | I16: 6 | J16: 30 | K16: =IF(H16=H15,K15+1,1) -> 11 | L16: 3|6| | M16: =IF(N16=1,OFFSET(effect!$A$1,MATCH(I16,effect!K:K,0)-1,0),0) -> 0 | N16: 0 | O16: 1 | P16: =Q16 -> 34 | Q16: =OFFSET(effect!$A$1,MATCH(B16,effect!B:B,0)-1,0) -> 34 | S16: 10 | T16: 1 | U16: 1 | V16: =W16&$V$1&X16&$V$1&$W$1&$X$1&$V$1&Y16&$V$1&$W$1 -> 301011|10|;400023|500|; | W16: =300000+A16 -> 301011 | X16: 10 | Y16: 500 | Z16: 16 | AA16: icon_27 | AB16: ·达到<span color='#ee6738'>筑基期</span>可通过境界突破领悟获得<br/>·通过<span color='#ee6738'>悟道台</span>获取碎片进行领悟获得 | AC16: 传闻某太玄门弟子在门派大比中被蜀山派嘲笑为缩头乌龟，气愤之下闭关练成此招。 | AD16: 2 | AE16: <span color='#ee6738'>境界突破</span>时领悟获得" | AF16: wenzi_img_13
A17: 1012 | B17: 混乱打击 | C17: 造成0~3倍%d点%s拳法伤害 | D17: 1 | E17: 1003 | F17: 2 | G17: 3 | H17: 1 | I17: 6 | J17: 30 | K17: =IF(H17=H16,K16+1,1) -> 12 | L17: 3|6| | M17: =IF(N17=1,OFFSET(effect!$A$1,MATCH(I17,effect!K:K,0)-1,0),0) -> 13 | N17: 1 | O17: 2 | P17: 41 | Q17: =OFFSET(effect!$A$1,MATCH(B17,effect!B:B,0)-1,0) -> #N/A | R17: 76 | S17: 10 | T17: 1 | U17: 1 | V17: =W17&$V$1&X17&$V$1&$W$1&$X$1&$V$1&Y17&$V$1&$W$1 -> 301012|10|;400023|1000|; | W17: =300000+A17 -> 301012 | X17: 10 | Y17: 1000 | Z17: 20 | AA17: icon_103 | AB17: ·达到<span color='#ee6738'>筑基期</span>可通过境界突破领悟获得<br/>·通过<span color='#ee6738'>悟道台</span>获取碎片进行领悟获得 | AC17: 传闻为蜀山仙师所传授，可以作为口诀心法配合剑招，使得凡俗剑术也威力大增。 | AD17: 2 | AE17: <span color='#ee6738'>境界突破</span>时领悟获得" | AF17: wenzi_img_14
A18: 1013 | B18: 崩山劲 | C18: 造成%d点%s拳法伤害，反弹30%受到的伤害，持续2回合 | D18: 1 | E18: 2000 | F18: 2 | G18: 2 | H18: 1 | I18: 5 | J18: 30 | K18: =IF(H18=H17,K17+1,1) -> 13 | L18: 4|3| | M18: =IF(N18=1,OFFSET(effect!$A$1,MATCH(I18,effect!K:K,0)-1,0),0) -> 18 | N18: 1 | O18: 2 | P18: =Q18 -> 41 | Q18: =OFFSET(effect!$A$1,MATCH(B18,effect!B:B,0)-1,0) -> 41 | S18: 10 | T18: 1 | U18: 1 | V18: =W18&$V$1&X18&$V$1&$W$1&$X$1&$V$1&Y18&$V$1&$W$1 -> 301013|10|;400023|750|; | W18: =300000+A18 -> 301013 | X18: 10 | Y18: 750 | Z18: 11 | AA18: icon_26 | AB18: ·达到<span color='#ee6738'>筑基期</span>可通过境界突破领悟获得<br/>·通过<span color='#ee6738'>悟道台</span>获取碎片进行领悟获得 | AC18: 崩山劲，源于已故的一位太玄门长老所创，他生前好斗，常群嘲之：打我等于打自己。 | AD18: 2 | AE18: <span color='#ee6738'>境界突破</span>时领悟获得" | AF18: wenzi_img_15
A19: 1014 | B19: 断脉杀 | C19: 对敌人造成%d点%s拳法伤害，对自己造成30%伤害 | D19: 1 | E19: 2000 | F19: 2 | G19: 1 | H19: 1 | I19: 6 | J19: 30 | K19: =IF(H19=H18,K18+1,1) -> 14 | L19: 3|6| | M19: =IF(N19=1,OFFSET(effect!$A$1,MATCH(I19,effect!K:K,0)-1,0),0) -> 13 | N19: 1 | O19: 2 | P19: 85 | Q19: =OFFSET(effect!$A$1,MATCH(B19,effect!B:B,0)-1,0) -> #N/A | S19: 10 | T19: 1 | U19: 1 | V19: =W19&$V$1&X19&$V$1&$W$1&$X$1&$V$1&Y19&$V$1&$W$1 -> 301014|10|;400023|500|; | W19: =300000+A19 -> 301014 | X19: 10 | Y19: 500 | Z19: 20 | AA19: icon_102 | AB19: ·达到<span color='#ee6738'>筑基期</span>可通过境界突破领悟获得<br/>·通过<span color='#ee6738'>悟道台</span>获取碎片进行领悟获得 | AC19: 断脉杀，爆发自己体内的灵气，产生超越当前境界的招式威力。但也会对自己的经脉造成严重损伤。 | AD19: 2 | AE19: <span color='#ee6738'>境界突破</span>时领悟获得" | AF19: wenzi_img_16
A20: 1015 | B20: 玉鼎掌 | C20: 造成%d点%s拳法伤害，上一招为拳法时，增加40%伤害 | D20: 1 | E20: 2000 | F20: 3 | G20: 1 | H20: 1 | I20: 5 | J20: 30 | K20: =IF(H20=H19,K19+1,1) -> 15 | L20: 3|6| | N20: 1 | O20: 2 | P20: =Q20 -> 78 | Q20: =OFFSET(effect!$A$1,MATCH(B20,effect!B:B,0)-1,0) -> 78 | S20: 10 | T20: 1 | U20: 1 | V20: =W20&$V$1&X20&$V$1&$W$1&$X$1&$V$1&Y20&$V$1&$W$1 -> 301015|10|;400023|500|; | W20: =300000+A20 -> 301015 | X20: 10 | Y20: 500 | Z20: 11 | AA20: icon_29 | AB20: ·达到<span color='#ee6738'>金丹期</span>可通过境界突破领悟获得<br/>·通过<span color='#ee6738'>悟道台</span>获取碎片进行领悟获得 | AC20: 莲花宗的真传掌法，灵力遍布手掌，犹如白玉，轰击敌人时无坚不摧。 | AD20: 2 | AE20: <span color='#ee6738'>境界突破</span>时领悟获得" | AF20: wenzi_img_17
A21: 1016 | B21: 还阳击 | C21: 造成%d点%s拳法伤害，每回合回复%f点生命，持续2回合 | D21: 1 | E21: 2000 | F21: 3 | G21: 2 | H21: 1 | I21: 2 | J21: 30 | K21: =IF(H21=H20,K20+1,1) -> 16 | L21: 2|5| | M21: =IF(N21=1,OFFSET(effect!$A$1,MATCH(I21,effect!K:K,0)-1,0),0) -> 16 | N21: 1 | O21: 2 | P21: 12 | Q21: =OFFSET(effect!$A$1,MATCH(B21,effect!B:B,0)-1,0) -> #N/A | S21: 10 | T21: 1 | U21: 1 | V21: =W21&$V$1&X21&$V$1&$W$1&$X$1&$V$1&Y21&$V$1&$W$1 -> 301016|10|;400023|750|; | W21: =300000+A21 -> 301016 | X21: 10 | Y21: 750 | Z21: 16 | AA21: icon_28 | AB21: ·达到<span color='#ee6738'>金丹期</span>可通过境界突破领悟获得<br/>·通过<span color='#ee6738'>悟道台</span>获取碎片进行领悟获得 | AC21: 灵丹派的真传招术，特殊的灵力运行方式，可以发出招术的同时，暗中恢复自己的伤势。 | AD21: 2 | AE21: <span color='#ee6738'>境界突破</span>时领悟获得" | AF21: wenzi_img_18
A22: 1017 | B22: 烈阳指 | C22: 造成%d点%s拳法伤害，叠加1层炎息 | D22: 1 | E22: 3000 | F22: 3 | G22: 2 | H22: 1 | I22: 4 | J22: 30 | K22: =IF(H22=H21,K21+1,1) -> 17 | L22: 3|6| | N22: 1 | O22: 2 | P22: =Q22 -> 96 | Q22: =OFFSET(effect!$A$1,MATCH(B22,effect!B:B,0)-1,0) -> 96 | S22: 10 | T22: 1 | U22: 1 | V22: =W22&$V$1&X22&$V$1&$W$1&$X$1&$V$1&Y22&$V$1&$W$1 -> 301017|10|;400023|750|; | W22: =300000+A22 -> 301017 | X22: 10 | Y22: 750 | Z22: 20 | AA22: icon_159 | AB22: ·达到<span color='#ee6738'>金丹期</span>可通过境界突破领悟获得<br/>·通过<span color='#ee6738'>悟道台</span>获取碎片进行领悟获得 | AC22: 金刚宗绝学，燃烧灵气，配合指法发出一道火焰烧伤敌人。 | AD22: 2 | AE22: <span color='#ee6738'>境界突破</span>时领悟获得" | AF22: wenzi_img_19
A23: 1018 | B23: 太玄揽臂 | C23: 造成%d点%s拳法伤害，上一招为拳法时，增加造成伤害50%的护甲 | D23: 1 | E23: 3000 | F23: 3 | G23: 3 | H23: 1 | I23: 6 | J23: 30 | K23: =IF(H23=H22,K22+1,1) -> 18 | L23: 4|3| | M23: =IF(N23=1,OFFSET(effect!$A$1,MATCH(I23,effect!K:K,0)-1,0),0) -> 13 | N23: 1 | O23: 2 | P23: 41 | Q23: =OFFSET(effect!$A$1,MATCH(B23,effect!B:B,0)-1,0) -> #N/A | S23: 10 | T23: 1 | U23: 1 | V23: =W23&$V$1&X23&$V$1&$W$1&$X$1&$V$1&Y23&$V$1&$W$1 -> 301018|10|;400023|1000|; | W23: =300000+A23 -> 301018 | X23: 10 | Y23: 1000 | Z23: 20 | AA23: icon_25 | AB23: ·达到<span color='#ee6738'>金丹期</span>可通过境界突破领悟获得<br/>·通过<span color='#ee6738'>悟道台</span>获取碎片进行领悟获得 | AC23: 太玄门揽臂，一切都与防护有关，抱元守一，岿然不动。 | AD23: 2 | AE23: <span color='#ee6738'>境界突破</span>时领悟获得" | AF23: wenzi_img_20
A24: 1019 | B24: 石破天惊拳 | C24: 造成%d点%s拳法伤害，额外造成当前护甲150%的伤害 | D24: 1 | E24: 3000 | F24: 2 | G24: 4 | H24: 1 | I24: 5 | J24: 30 | K24: =IF(H24=H23,K23+1,1) -> 19 | L24: 3|6| | M24: =effect!A9 -> 4 | N24: 1 | O24: 2 | P24: =Q24 -> 117 | Q24: =OFFSET(effect!$A$1,MATCH(B24,effect!B:B,0)-1,0) -> 117 | S24: 10 | T24: 1 | V24: =W24&$V$1&X24&$V$1&$W$1&$X$1&$V$1&Y24&$V$1&$W$1 -> 301019|10|;400023|1500|; | W24: =300000+A24 -> 301019 | X24: 10 | Y24: 1500 | Z24: 20 | AA24: icon_105 | AB24: ·达到<span color='#ee6738'>筑基期</span>可通过境界突破领悟获得<br/>·通过<span color='#ee6738'>悟道台</span>获取碎片进行领悟获得 | AC24: 被称为最没有太玄门风格的招式名字，但创下这招法术的弟子偏偏喜欢这个名字。 | AD24: 2 | AE24: <span color='#ee6738'>境界突破</span>时领悟获得" | AF24: wenzi_img_21
A25: 1020 | B25: 血饮狂歌 | C25: 造成%d点%s拳法伤害，血量低于50%时，获得30%吸血效果 | D25: 1 | E25: 3000 | F25: 3 | G25: 4 | H25: 1 | I25: 4 | J25: 30 | K25: =IF(H25=H24,K24+1,1) -> 20 | L25: 3|6| | M25: =IF(N25=1,OFFSET(effect!$A$1,MATCH(I25,effect!K:K,0)-1,0),0) -> 14 | N25: 1 | O25: 2 | P25: =Q25 -> 86 | Q25: =OFFSET(effect!$A$1,MATCH(B25,effect!B:B,0)-1,0) -> 86 | S25: 10 | T25: 1 | V25: =W25&$V$1&X25&$V$1&$W$1&$X$1&$V$1&Y25&$V$1&$W$1 -> 301020|10|;400023|1500|; | W25: =300000+A25 -> 301020 | X25: 10 | Y25: 1500 | Z25: 20 | AA25: icon_104 | AB25: ·达到<span color='#ee6738'>金丹期</span>可通过境界突破领悟获得<br/>·通过<span color='#ee6738'>悟道台</span>获取碎片进行领悟获得 | AC25: 血魔宫的高级招术，十分擅长在绝境时反击敌人，断绝灵气，汲取敌人生命力。 | AD25: 2 | AE25: <span color='#ee6738'>境界突破</span>时领悟获得" | AF25: wenzi_img_22
A26: =H26*1000+F26*100+K26 -> 1401 | B26: 燃魂拳 | C26: 造成%d点%s拳法伤害，血量低于50%时，伤害增加40% | D26: 1 | E26: 4000 | F26: 4 | G26: 2 | H26: 1 | I26: 4 | J26: 30 | K26: =IF(F26=F25,K25+1,1) -> 1 | L26: 3|6| | M26: =effect!A9 -> 4 | N26: 1 | O26: 2 | P26: =Q26 -> 5 | Q26: =OFFSET(effect!$A$1,MATCH(B26,effect!B:B,0)-1,0) -> 5 | S26: 10 | T26: 1 | V26: =W26&$V$1&X26&$V$1&$W$1&$X$1&$V$1&Y26&$V$1&$W$1 -> 301401|10|;400023|750|; | W26: =300000+A26 -> 301401 | X26: 10 | Y26: 750 | Z26: 20 | AB26: ·达到<span color='#ee6738'>元婴期</span>可通过境界突破领悟获得<br/>·通过<span color='#ee6738'>悟道台</span>获取碎片进行领悟获得 | AC26: 血魔宫的真传招术，一般用于终结击杀敌人时使用。无数正道人士饮恨在这一招之下。 | AD26: 2 | AE26: <span color='#ee6738'>境界突破</span>时领悟获得" | AF26: wenzi_img_23
A27: =H27*1000+F27*100+K27 -> 1402 | B27: 焚天掌 | C27: 造成%d点%s拳法伤害，叠加2层炎息 | D27: 1 | E27: 4000 | F27: 4 | G27: 2 | H27: 1 | I27: 4 | J27: 30 | K27: =IF(F27=F26,K26+1,1) -> 2 | L27: 4|3| | M27: =IF(N27=1,OFFSET(effect!$A$1,MATCH(I27,effect!K:K,0)-1,0),0) -> 14 | N27: 1 | O27: 2 | P27: 13 | Q27: =OFFSET(effect!$A$1,MATCH(B27,effect!B:B,0)-1,0) -> #N/A | S27: 10 | T27: 1 | V27: =W27&$V$1&X27&$V$1&$W$1&$X$1&$V$1&Y27&$V$1&$W$1 -> 301402|10|;400023|750|; | W27: =300000+A27 -> 301402 | X27: 10 | Y27: 750 | Z27: 20 | AB27: ·达到<span color='#ee6738'>元婴期</span>可通过境界突破领悟获得<br/>·通过<span color='#ee6738'>悟道台</span>获取碎片进行领悟获得 | AC27: 金刚宗绝学，催动灵气剧烈燃烧，让自己的招术产生烈焱之力，破坏力惊人。 | AD27: 2 | AE27: <span color='#ee6738'>境界突破</span>时领悟获得" | AF27: wenzi_img_24
A28: =H28*1000+F28*100+K28 -> 1403 | B28: 玉龙杀 | C28: 造成%d点%s拳法伤害，上一招为拳法时，增加50%伤害 | D28: 1 | E28: 4000 | F28: 4 | G28: 2 | H28: 1 | I28: 6 | J28: 30 | K28: =IF(F28=F27,K27+1,1) -> 3 | L28: 3|6| | M28: =IF(N28=1,OFFSET(effect!$A$1,MATCH(I28,effect!K:K,0)-1,0),0) -> 13 | N28: 1 | O28: 2 | P28: 12 | Q28: =OFFSET(effect!$A$1,MATCH(B28,effect!B:B,0)-1,0) -> #N/A | S28: 10 | T28: 1 | V28: =W28&$V$1&X28&$V$1&$W$1&$X$1&$V$1&Y28&$V$1&$W$1 -> 301403|10|;400023|750|; | W28: =300000+A28 -> 301403 | X28: 10 | Y28: 750 | Z28: 20 | AB28: ·达到<span color='#ee6738'>元婴期</span>可通过境界突破领悟获得<br/>·通过<span color='#ee6738'>悟道台</span>获取碎片进行领悟获得 | AC28: 太玄门的绝学之一，拳法灵气召出龙形气浪轰击敌人，威力极为惊人。 | AD28: 2 | AE28: <span color='#ee6738'>境界突破</span>时领悟获得" | AF28: wenzi_img_25
A29: =H29*1000+F29*100+K29 -> 1404 | B29: 冲虚连指 | C29: 造成2~5次%d点%s拳法伤害 | D29: 1 | E29: 4000 | F29: 4 | G29: 3 | H29: 1 | I29: 5 | J29: 30 | K29: =IF(F29=F28,K28+1,1) -> 4 | L29: 3|6| | M29: =IF(N29=1,OFFSET(effect!$A$1,MATCH(I29,effect!K:K,0)-1,0),0) -> 18 | N29: 1 | O29: 2 | P29: 12 | Q29: =OFFSET(effect!$A$1,MATCH(B29,effect!B:B,0)-1,0) -> #N/A | S29: 10 | T29: 1 | V29: =W29&$V$1&X29&$V$1&$W$1&$X$1&$V$1&Y29&$V$1&$W$1 -> 301404|10|;400023|1000|; | W29: =300000+A29 -> 301404 | X29: 10 | Y29: 1000 | Z29: 9 | AB29: ·达到<span color='#ee6738'>元婴期</span>可通过境界突破领悟获得<br/>·通过<span color='#ee6738'>悟道台</span>获取碎片进行领悟获得 | AC29: 太玄门真传拳法之一，修炼此招术到高深处，可以一敌二，发出数道法力轰击敌人。 | AD29: 2 | AE29: <span color='#ee6738'>境界突破</span>时领悟获得" | AF29: wenzi_img_26
A30: =H30*1000+F30*100+K30 -> 1405 | B30: 金刚伏魔拳 | C30: 造成%d点%s拳法伤害，本回合每出一张拳法牌，增加造成伤害30%的护甲 | D30: 1 | E30: 4000 | F30: 4 | G30: 4 | H30: 1 | I30: 1 | J30: 30 | K30: =IF(F30=F29,K29+1,1) -> 5 | V30: =W30&$V$1&X30&$V$1&$W$1&$X$1&$V$1&Y30&$V$1&$W$1 -> 301405|10|;400023|1500|; | W30: =300000+A30 -> 301405 | X30: 10 | Y30: 1500
A31: =H31*1000+F31*100+K31 -> 1501 | B31: 九杀拳 | C31: 对敌人造成大量拳法伤害，对自己造成20%伤害 | D31: 1 | E31: 5000 | F31: 5 | G31: 2 | H31: 1 | I31: 6 | J31: 30 | K31: =IF(F31=F29,K29+1,1) -> 1 | L31: 3|6| | M31: =IF(N31=1,OFFSET(effect!$A$1,MATCH(I31,effect!K:K,0)-1,0),0) -> 13 | N31: 1 | O31: 2 | P31: 12 | Q31: =OFFSET(effect!$A$1,MATCH(B31,effect!B:B,0)-1,0) -> #N/A | S31: 10 | T31: 1 | V31: =W31&$V$1&X31&$V$1&$W$1&$X$1&$V$1&Y31&$V$1&$W$1 -> 301501|10|;400023|750|; | W31: =300000+A31 -> 301501 | X31: 10 | Y31: 750 | Z31: 16 | AB31: ·达到<span color='#ee6738'>元婴期</span>可通过境界突破领悟获得<br/>·通过<span color='#ee6738'>悟道台</span>获取碎片进行领悟获得 | AC31: 血魔老祖的成名绝技，以滔天魔力无可匹敌闻名于修仙界。 | AD31: 2 | AE31: <span color='#ee6738'>境界突破</span>时领悟获得" | AF31: wenzi_img_27
A32: =H32*1000+F32*100+K32 -> 1502 | B32: 玄冥指 | C32: 造成%d点%s拳法伤害，叠加2层冰冻 | D32: 1 | E32: 5000 | F32: 5 | G32: 2 | H32: 1 | I32: 5 | J32: 30 | K32: =IF(F32=F31,K31+1,1) -> 2 | L32: 3|6| | M32: =IF(N32=1,OFFSET(effect!$A$1,MATCH(I32,effect!K:K,0)-1,0),0) -> 0 | N32: 0 | O32: 2 | P32: 12 | Q32: =OFFSET(effect!$A$1,MATCH(B32,effect!B:B,0)-1,0) -> #N/A | S32: 10 | T32: 1 | V32: =W32&$V$1&X32&$V$1&$W$1&$X$1&$V$1&Y32&$V$1&$W$1 -> 301502|10|;400023|750|; | W32: =300000+A32 -> 301502 | X32: 10 | Y32: 750 | Z32: 20 | AB32: ·达到<span color='#ee6738'>炼气期</span>可通过境界突破领悟获得<br/>·通过<span color='#ee6738'>悟道台</span>获取碎片进行领悟获得 | AC32: 血魔老祖的不死法术，用血魔功法断绝自己气机，再重新组合身体的方式，可以暂时免疫致命伤。 | AD32: 2 | AE32: <span color='#ee6738'>境界突破</span>时领悟获得" | AF32: wenzi_img_28
A33: =H33*1000+F33*100+K33 -> 1503 | B33: 血冥爪 | C33: 造成%d点%s拳法伤害，血量低于50%时，获得40%吸血效果 | D33: 1 | E33: 5000 | F33: 5 | G33: 2 | H33: 1 | I33: 6 | J33: 30 | K33: =IF(F33=F32,K32+1,1) -> 3 | L33: 3|6| | M33: =IF(N33=1,OFFSET(effect!$A$1,MATCH(I33,effect!K:K,0)-1,0),0) -> 13 | N33: 1 | O33: 2 | P33: 90 | Q33: =OFFSET(effect!$A$1,MATCH(B33,effect!B:B,0)-1,0) -> #N/A | S33: 10 | T33: 1 | V33: =W33&$V$1&X33&$V$1&$W$1&$X$1&$V$1&Y33&$V$1&$W$1 -> 301503|10|;400023|750|; | W33: =300000+A33 -> 301503 | X33: 10 | Y33: 750 | Z33: 33 | AB33: ·达到<span color='#ee6738'>炼气期</span>可通过境界突破领悟获得<br/>·通过<span color='#ee6738'>悟道台</span>获取碎片进行领悟获得 | AC33: 太玄冲门，习练太玄拳法的弟子说，他们曾用这一招撞开过无数贼寇的城门。 | AD33: 2 | AE33: <span color='#ee6738'>境界突破</span>时领悟获得" | AF33: wenzi_img_29
A34: =H34*1000+F34*100+K34 -> 1504 | B34: 血煞化罡 | C34: 获得本回合累计受到伤害30%的护甲 | D34: 1 | E34: 5000 | F34: 5 | G34: 3 | H34: 1 | I34: 4 | J34: 30 | K34: =IF(F34=F33,K33+1,1) -> 4 | V34: =W34&$V$1&X34&$V$1&$W$1&$X$1&$V$1&Y34&$V$1&$W$1 -> 301504|10|;400023|1000|; | W34: =300000+A34 -> 301504 | X34: 10 | Y34: 1000
A35: =H35*1000+F35*100+K35 -> 1505 | B35: 混元真罡 | C35: 造成%d点%s拳法伤害，额外造成当前护甲200%的伤害 | D35: 1 | E35: 5000 | F35: 5 | G35: 4 | H35: 1 | I35: 5 | J35: 30 | K35: =IF(F35=F34,K34+1,1) -> 5 | V35: =W35&$V$1&X35&$V$1&$W$1&$X$1&$V$1&Y35&$V$1&$W$1 -> 301505|10|;400023|1500|; | W35: =300000+A35 -> 301505 | X35: 10 | Y35: 1500
A36: =H36*1000+F36*100+K36 -> 1601 | B36: 璇玑杀 | C36: 造成%d点%s拳法伤害，血量低于50%时，伤害增加50% | D36: 0 | E36: 6000 | F36: 6 | G36: 3 | H36: 1 | I36: 6 | J36: 30 | K36: =IF(F36=F33,K33+1,1) -> 1 | L36: 3|6| | M36: 10 | N36: 1 | O36: 2 | P36: 13 | Q36: =OFFSET(effect!$A$1,MATCH(B36,effect!B:B,0)-1,0) -> #N/A | S36: 10 | T36: 1 | V36: =W36&$V$1&X36&$V$1&$W$1&$X$1&$V$1&Y36&$V$1&$W$1 -> 301601|10|;400023|1000|; | W36: =300000+A36 -> 301601 | X36: 10 | Y36: 1000 | Z36: 20 | AB36: ·达到<span color='#ee6738'>炼气期</span>可通过境界突破领悟获得<br/>·通过<span color='#ee6738'>悟道台</span>获取碎片进行领悟获得 | AC36: 血魔老祖在太玄门和蜀山的联手袭杀下，绝境之中领悟的招术，通过灵力挖掘身体全部潜力，威力恐怖。 | AD36: 2 | AE36: <span color='#ee6738'>境界突破</span>时领悟获得" | AF36: wenzi_img_30
A37: =H37*1000+F37*100+K37 -> 1602 | B37: 灭魔掌 | C37: 造成%d点%s拳法伤害，本回合每出一张拳法牌，伤害增加35% | D37: 0 | E37: 6000 | F37: 6 | G37: 4 | H37: 1 | I37: 5 | J37: 30 | K37: =IF(F37=F36,K36+1,1) -> 2 | L37: 3|6| | M37: =IF(N37=1,OFFSET(effect!$A$1,MATCH(I37,effect!K:K,0)-1,0),0) -> 18 | N37: 1 | O37: 2 | P37: 1 | Q37: =OFFSET(effect!$A$1,MATCH(B37,effect!B:B,0)-1,0) -> #N/A | S37: 10 | T37: 1 | V37: =W37&$V$1&X37&$V$1&$W$1&$X$1&$V$1&Y37&$V$1&$W$1 -> 301602|10|;400023|1500|; | W37: =300000+A37 -> 301602 | X37: 10 | Y37: 1500 | Z37: 11 | AB37: ·达到<span color='#ee6738'>筑基期</span>可通过境界突破领悟获得<br/>·通过<span color='#ee6738'>悟道台</span>获取碎片进行领悟获得 | AC37: 太玄门上一代掌门在重伤闭关后领悟的招术，据说是一招秘传的拳法，专门用于对付血魔老祖。 | AD37: 2 | AE37: <span color='#ee6738'>境界突破</span>时领悟获得" | AF37: wenzi_img_31
A38: =H38*1000+F38*100+K38 -> 1603 | B38: 贯星角 | C38: 造成0~5倍%d点%s拳法伤害 | D38: 0 | E38: 6000 | F38: 6 | G38: 4 | H38: 1 | I38: 5 | J38: 30 | K38: =IF(F38=F37,K37+1,1) -> 3 | L38: 4|3| | M38: =IF(N38=1,OFFSET(effect!$A$1,MATCH(I38,effect!K:K,0)-1,0),0) -> 18 | N38: 1 | O38: 2 | P38: 1 | Q38: =OFFSET(effect!$A$1,MATCH(B38,effect!B:B,0)-1,0) -> #N/A | S38: 10 | T38: 1 | V38: =W38&$V$1&X38&$V$1&$W$1&$X$1&$V$1&Y38&$V$1&$W$1 -> 301603|10|;400023|1500|; | W38: =300000+A38 -> 301603 | X38: 10 | Y38: 1500 | Z38: 11 | AB38: ·达到<span color='#ee6738'>筑基期</span>可通过境界突破领悟获得<br/>·通过<span color='#ee6738'>悟道台</span>获取碎片进行领悟获得 | AC38: 传闻中金仙梦中传授的技法，有缘人方能习得。 | AD38: 2 | AE38: <span color='#ee6738'>境界突破</span>时领悟获得" | AF38: wenzi_img_32
A39: =H39*1000+F39*100+K39 -> 1604 | B39: 却死逆命 | C39: 1回合内，自身血量不会降低到1以下 | D39: 0 | E39: 6000 | F39: 6 | G39: 4 | H39: 1 | I39: 5 | J39: 30 | K39: =IF(F39=F38,K38+1,1) -> 4 | L39: 4|3| | M39: =IF(N39=1,OFFSET(effect!$A$1,MATCH(I39,effect!K:K,0)-1,0),0) -> 18 | N39: 1 | O39: 2 | P39: 1 | Q39: =OFFSET(effect!$A$1,MATCH(B39,effect!B:B,0)-1,0) -> #N/A | S39: 10 | T39: 1 | V39: =W39&$V$1&X39&$V$1&$W$1&$X$1&$V$1&Y39&$V$1&$W$1 -> 301604|10|;400023|1500|; | W39: =300000+A39 -> 301604 | X39: 10 | Y39: 1500 | Z39: 11 | AB39: ·达到<span color='#ee6738'>筑基期</span>可通过境界突破领悟获得<br/>·通过<span color='#ee6738'>悟道台</span>获取碎片进行领悟获得 | AC39: 传闻中金仙梦中传授的技法，有缘人方能习得。 | AD39: 2 | AE39: <span color='#ee6738'>境界突破</span>时领悟获得" | AF39: wenzi_img_32
A40: 2001 | B40: 劈剑式 | C40: 造成%d点%s剑法伤害 | D40: 1 | E40: 1000 | F40: 1 | G40: 1 | H40: 2 | I40: 1 | J40: 30 | K40: =IF(H40=H38,K38+1,1) -> 1 | L40: 3|6| | M40: =IF(N40=1,OFFSET(effect!$A$1,MATCH(I40,effect!K:K,0)-1,0),0) -> 15 | N40: 1 | O40: 2 | P40: =Q40 -> 54 | Q40: =OFFSET(effect!$A$1,MATCH(B40,effect!B:B,0)-1,0) -> 54 | S40: 10 | T40: 1 | U40: 1 | V40: =W40&$V$1&X40&$V$1&$W$1&$X$1&$V$1&Y40&$V$1&$W$1 -> 302001|10|;400023|500|; | W40: =300000+A40 -> 302001 | X40: 10 | Y40: 500 | Z40: 31 | AA40: icon_07 | AB40: ·达到<span color='#ee6738'>锻体期</span>可通流派选择获得<br/>·通过<span color='#ee6738'>悟道台</span>获取碎片进行领悟获得 | AC40: 剑术的基础招式，若是刀法，武林人士会称之为力劈华山。 | AD40: 2 | AE40: <span color='#ee6738'>境界突破</span>时领悟获得" | AF40: wenzi_img_33
...

Sheet card
A1: 卡牌表 | J1: 5 | K1: 4 | L1: 5 | M1: 5 | N1: 10 | S1: 3 | W1: 0.3 | AA1: 6 | AF1: | | AJ1: ; | AM1: 400023
A2: ID | B2: 技能名称 | C2: 武器属性 =1，拳法 =2，剑法 =3，法术 =4，无 | D2: 五行属性 =1，金 =2，木 =3，水 =4，火 =5，土 =6，无属性 | E2: 描述,支持X1|X2|X4|代入到描述中,具索引param | F2: 描述,支持X1|X2|X3|代入到描述中,具索引param | G2: 限制条件增加资质 | H2: 技能效果费用 | I2: 归属 0.主角 1.怪物 | J2: 境界 | K2: 品质 | L2: 消耗费用 | M2: 真实费用 | N2: 当前等级 | O2: 消耗物品 （多个物品用|；分隔） | P2: 对自己造成伤害与招式伤害比例 | Q2: 卡牌类型,索引card_type表 | R2: 伤害类型 | S2: 固定效果值(取整) | T2: 效果关联属性类型 1.根骨 2.悟性 3.魅力 4.神识 5.机缘 | U2: 索引系数编号 | V2: 属性对伤害成长 | W2: 属性对伤害成长（旧） | X2: 固定效果资质 | Y2: 总资质=固定+技能 | Z2: 单位费用资质 | AA2: 解锁卡牌战力 | AB2: 战力索引值（勿删） | AC2: 功能效果触发方式 | AD2: 触发buffid | AE2: 触发条件值 | AF2: 功能效果。索引skillid | AG2: 技能变化 | AH2: 触发技能时的特殊效果 1.真伤 2.吸血 （客户端无效） | AI2: 是否判断减少消耗（客户端无效） | AJ2: 升级所需消耗（物品id） | AK2: 升级物品 | AL2: 数量 | AM2: 功法点 | AN2: 升级至下一级的ID | AO2: 可使用万能碎片id 不填则不可使用 | AP2: 技能生效时候播放特效 | AQ2: 对应buff_id （%f代字符所对应的数值取buff id计算的数值）
A3: INT | B3: STRING | C3: INT | D3: INT | E3: STRING | F3: STRING | L3: INT | N3: INT | O3: STRING | P3: INT | Q3: INT | R3: INT | S3: INT | T3: INT | V3: FLOAT | AA3: INT | AC3: INT | AD3: INT | AE3: INT | AF3: STRING | AH3: INT | AI3: INT | AJ3: STRING | AN3: INT | AO3: INT | AP3: STRING | AQ3: INT
A4: ID | B4: name | C4: weapon | D4: element | E4: describe | F4: describe2 | L4: cost | N4: lev | O4: cost_item | P4: hurt_self | Q4: card_type | R4: type | S4: fixed_value | T4: attribute | V4: attribute_coefficient | AA4: card_combat | AC4: trigger | AD4: trigger_buff | AE4: trigger_value | AF4: skill_id | AH4: if_ture_effect | AI4: if_reduce_energy | AJ4: uplev_cost | AN4: uplev_next_id | AO4: substitute_id | AP4: skill_effect | AQ4: buff_id
A5: ID | C5: weapon | D5: element | L5: cost | N5: lev | O5: cost_item | P5: hurt_self | Q5: card_type | R5: type | S5: fixed_value | T5: attribute | V5: attribute_coefficient | AA5: card_combat | AC5: trigger | AD5: trigger_buff | AE5: trigger_value | AF5: skill_id | AH5: if_ture_effect | AI5: if_reduce_energy | AJ5: uplev_cost | AN5: uplev_next_id
A6: =Q6*1000+N6 -> 1001001 | B6: 红玉指 | C6: 1 | D6: 6 | E6: 造成%d点%s拳法伤害 | G6: -3 | H6: =IF(R6=0,Y6,0) -> 0 | J6: =OFFSET(card_type!$F$1,MATCH(Q6,card_type!A:A,0)-1,0) -> 1 | K6: =OFFSET(card_type!$G$1,MATCH(Q6,card_type!A:A,0)-1,0) -> 1 | L6: 1 | M6: =L6-H6 -> 1 | N6: =IF(B5=B6,N5+1,1) -> 1 | Q6: =OFFSET(card_type!$A$1,MATCH(card!B6,card_type!B:B,0)-1,0) -> 1001 | R6: 1 | S6: =ROUND(IF(R6=0,0,IF(R6=1,X6*$S$1,IF(R6=2,X6*$S$1*buff的资质计算!$E$2,IF(R6=3,X6*$S$1*buff的资质计算!$E$3,0)))),0)*0 -> 0 | T6: 1 | U6: =J6*10+K6 -> 11 | V6: =ROUND((OFFSET(卡牌辅助配置表!$O$1,MATCH(U6,卡牌辅助配置表!M:M,0)-1,0)+(N6-1)*OFFSET(卡牌辅助配置表!$P$1,MATCH(U6,卡牌辅助配置表!M:M,0)-1,0))*M6,2) -> 6.27 | W6: =ROUND(IF(R6=0,0,IF(R6=1,X6*$W$1,IF(R6=2,X6*$W$1*buff的资质计算!$E$2,IF(R6=3,X6*$W$1*buff的资质计算!$E$3,0)))),2) -> 0.6 | X6: =M6*($M$1+(J6-1)*$J$1+(K6-1)*$K$1)+G6+$J$1*(N6-1)/$N$1 -> 2 | Y6: =X6+H6 -> 2 | Z6: =Y6/M6 -> 2 | AA6: =OFFSET(卡牌辅助配置表!$AD$1,MATCH(AB6,卡牌辅助配置表!AB:AB,0)-1,0) -> 18 | AB6: =J6*1000+K6*100+N6 -> 1101 | AF6: =((Q6*1000+1)*10+1)&$AF$1 -> 10010011| | AJ6: =IF(AN6=0,0,IF(AL6=0,$AM$1&$AF$1&AM6&$AF$1&$AJ$1,AK6&$AF$1&AL6&$AF$1&$AJ$1&$AM$1&$AF$1&AM6&$AF$1&$AJ$1)) -> 400023|700|; | AK6: =OFFSET([1]item_type!$A$1,MATCH(Q6,[1]item_type!$G:$G,0)-1,0) -> 301001 | AM6: =IF(B6=B7,OFFSET(卡牌辅助配置表!$AE$1,MATCH(AB6,卡牌辅助配置表!AB:AB,0),0),0) -> 700 | AN6: =IF(B6=B7,A6+1,0) -> 1001002 | AP6: =IF(AC6=0,0,IF(AC6=12,0,OFFSET(effect!$N$1,MATCH(K6,effect!M:M,0)-1,0))) -> 0
A7: =Q7*1000+N7 -> 1001002 | B7: 红玉指 | C7: 1 | D7: 6 | E7: 造成%d点%s拳法伤害 | G7: -3 | H7: =IF(R7=0,Y7,0) -> 0 | J7: =OFFSET(card_type!$F$1,MATCH(Q7,card_type!A:A,0)-1,0) -> 1 | K7: =OFFSET(card_type!$G$1,MATCH(Q7,card_type!A:A,0)-1,0) -> 1 | L7: 1 | M7: 1 | N7: =IF(B6=B7,N6+1,1) -> 2 | Q7: =OFFSET(card_type!$A$1,MATCH(card!B7,card_type!B:B,0)-1,0) -> 1001 | R7: 1 | S7: =ROUND(IF(R7=0,0,IF(R7=1,X7*$S$1,IF(R7=2,X7*$S$1*buff的资质计算!$E$2,IF(R7=3,X7*$S$1*buff的资质计算!$E$3,0)))),0)*0 -> 0 | T7: 1 | U7: =J7*10+K7 -> 11 | V7: =ROUND((OFFSET(卡牌辅助配置表!$O$1,MATCH(U7,卡牌辅助配置表!M:M,0)-1,0)+(N7-1)*OFFSET(卡牌辅助配置表!$P$1,MATCH(U7,卡牌辅助配置表!M:M,0)-1,0))*M7,2) -> 6.48 | W7: =ROUND(IF(R7=0,0,IF(R7=1,X7*$W$1,IF(R7=2,X7*$W$1*buff的资质计算!$E$2,IF(R7=3,X7*$W$1*buff的资质计算!$E$3,0)))),2) -> 0.75 | X7: =M7*($M$1+(J7-1)*$J$1+(K7-1)*$K$1)+G7+$J$1*(N7-1)/$N$1 -> 2.5 | Y7: =X7+H7 -> 2.5 | Z7: =Y7/M7 -> 2.5 | AA7: =OFFSET(卡牌辅助配置表!$AD$1,MATCH(AB7,卡牌辅助配置表!AB:AB,0)-1,0) -> 36 | AB7: =J7*1000+K7*100+N7 -> 1102 | AF7: =((Q7*1000+1)*10+1)&$AF$1 -> 10010011| | AJ7: =IF(AN7=0,0,IF(AL7=0,$AM$1&$AF$1&AM7&$AF$1&$AJ$1,AK7&$AF$1&AL7&$AF$1&$AJ$1&$AM$1&$AF$1&AM7&$AF$1&$AJ$1)) -> 400023|900|; | AK7: =OFFSET([1]item_type!$A$1,MATCH(Q7,[1]item_type!$G:$G,0)-1,0) -> 301001 | AM7: =IF(B7=B8,OFFSET(卡牌辅助配置表!$AE$1,MATCH(AB7,卡牌辅助配置表!AB:AB,0),0),0) -> 900 | AN7: =IF(B7=B8,A7+1,0) -> 1001003 | AP7: =IF(AC7=0,0,IF(AC7=12,0,OFFSET(effect!$N$1,MATCH(K7,effect!M:M,0)-1,0))) -> 0
A8: =Q8*1000+N8 -> 1001003 | B8: 红玉指 | C8: 1 | D8: 6 | E8: 造成%d点%s拳法伤害 | G8: -3 | H8: =IF(R8=0,Y8,0) -> 0 | J8: =OFFSET(card_type!$F$1,MATCH(Q8,card_type!A:A,0)-1,0) -> 1 | K8: =OFFSET(card_type!$G$1,MATCH(Q8,card_type!A:A,0)-1,0) -> 1 | L8: 1 | M8: 1 | N8: =IF(B7=B8,N7+1,1) -> 3 | Q8: =OFFSET(card_type!$A$1,MATCH(card!B8,card_type!B:B,0)-1,0) -> 1001 | R8: 1 | S8: =ROUND(IF(R8=0,0,IF(R8=1,X8*$S$1,IF(R8=2,X8*$S$1*buff的资质计算!$E$2,IF(R8=3,X8*$S$1*buff的资质计算!$E$3,0)))),0)*0 -> 0 | T8: 1 | U8: =J8*10+K8 -> 11 | V8: =ROUND((OFFSET(卡牌辅助配置表!$O$1,MATCH(U8,卡牌辅助配置表!M:M,0)-1,0)+(N8-1)*OFFSET(卡牌辅助配置表!$P$1,MATCH(U8,卡牌辅助配置表!M:M,0)-1,0))*M8,2) -> 6.69 | W8: =ROUND(IF(R8=0,0,IF(R8=1,X8*$W$1,IF(R8=2,X8*$W$1*buff的资质计算!$E$2,IF(R8=3,X8*$W$1*buff的资质计算!$E$3,0)))),2) -> 0.9 | X8: =M8*($M$1+(J8-1)*$J$1+(K8-1)*$K$1)+G8+$J$1*(N8-1)/$N$1 -> 3 | Y8: =X8+H8 -> 3 | Z8: =Y8/M8 -> 3 | AA8: =OFFSET(卡牌辅助配置表!$AD$1,MATCH(AB8,卡牌辅助配置表!AB:AB,0)-1,0) -> 54 | AB8: =J8*1000+K8*100+N8 -> 1103 | AF8: =((Q8*1000+1)*10+1)&$AF$1 -> 10010011| | AJ8: =IF(AN8=0,0,IF(AL8=0,$AM$1&$AF$1&AM8&$AF$1&$AJ$1,AK8&$AF$1&AL8&$AF$1&$AJ$1&$AM$1&$AF$1&AM8&$AF$1&$AJ$1)) -> 400023|1100|; | AK8: =OFFSET([1]item_type!$A$1,MATCH(Q8,[1]item_type!$G:$G,0)-1,0) -> 301001 | AM8: =IF(B8=B9,OFFSET(卡牌辅助配置表!$AE$1,MATCH(AB8,卡牌辅助配置表!AB:AB,0),0),0) -> 1100 | AN8: =IF(B8=B9,A8+1,0) -> 1001004 | AP8: =IF(AC8=0,0,IF(AC8=12,0,OFFSET(effect!$N$1,MATCH(K8,effect!M:M,0)-1,0))) -> 0
A9: =Q9*1000+N9 -> 1001004 | B9: 红玉指 | C9: 1 | D9: 6 | E9: 造成%d点%s拳法伤害 | G9: -3 | H9: =IF(R9=0,Y9,0) -> 0 | J9: =OFFSET(card_type!$F$1,MATCH(Q9,card_type!A:A,0)-1,0) -> 1 | K9: =OFFSET(card_type!$G$1,MATCH(Q9,card_type!A:A,0)-1,0) -> 1 | L9: 1 | M9: 1 | N9: =IF(B8=B9,N8+1,1) -> 4 | Q9: =OFFSET(card_type!$A$1,MATCH(card!B9,card_type!B:B,0)-1,0) -> 1001 | R9: 1 | S9: =ROUND(IF(R9=0,0,IF(R9=1,X9*$S$1,IF(R9=2,X9*$S$1*buff的资质计算!$E$2,IF(R9=3,X9*$S$1*buff的资质计算!$E$3,0)))),0)*0 -> 0 | T9: 1 | U9: =J9*10+K9 -> 11 | V9: =ROUND((OFFSET(卡牌辅助配置表!$O$1,MATCH(U9,卡牌辅助配置表!M:M,0)-1,0)+(N9-1)*OFFSET(卡牌辅助配置表!$P$1,MATCH(U9,卡牌辅助配置表!M:M,0)-1,0))*M9,2) -> 6.9 | W9: =ROUND(IF(R9=0,0,IF(R9=1,X9*$W$1,IF(R9=2,X9*$W$1*buff的资质计算!$E$2,IF(R9=3,X9*$W$1*buff的资质计算!$E$3,0)))),2) -> 1.05 | X9: =M9*($M$1+(J9-1)*$J$1+(K9-1)*$K$1)+G9+$J$1*(N9-1)/$N$1 -> 3.5 | Y9: =X9+H9 -> 3.5 | Z9: =Y9/M9 -> 3.5 | AA9: =OFFSET(卡牌辅助配置表!$AD$1,MATCH(AB9,卡牌辅助配置表!AB:AB,0)-1,0) -> 72 | AB9: =J9*1000+K9*100+N9 -> 1104 | AF9: =((Q9*1000+1)*10+1)&$AF$1 -> 10010011| | AJ9: =IF(AN9=0,0,IF(AL9=0,$AM$1&$AF$1&AM9&$AF$1&$AJ$1,AK9&$AF$1&AL9&$AF$1&$AJ$1&$AM$1&$AF$1&AM9&$AF$1&$AJ$1)) -> 400023|1300|; | AK9: =OFFSET([1]item_type!$A$1,MATCH(Q9,[1]item_type!$G:$G,0)-1,0) -> 301001 | AM9: =IF(B9=B10,OFFSET(卡牌辅助配置表!$AE$1,MATCH(AB9,卡牌辅助配置表!AB:AB,0),0),0) -> 1300 | AN9: =IF(B9=B10,A9+1,0) -> 1001005 | AP9: =IF(AC9=0,0,IF(AC9=12,0,OFFSET(effect!$N$1,MATCH(K9,effect!M:M,0)-1,0))) -> 0
A10: =Q10*1000+N10 -> 1001005 | B10: 红玉指 | C10: 1 | D10: 6 | E10: 造成%d点%s拳法伤害 | G10: -3 | H10: =IF(R10=0,Y10,0) -> 0 | J10: =OFFSET(card_type!$F$1,MATCH(Q10,card_type!A:A,0)-1,0) -> 1 | K10: =OFFSET(card_type!$G$1,MATCH(Q10,card_type!A:A,0)-1,0) -> 1 | L10: 1 | M10: 1 | N10: =IF(B9=B10,N9+1,1) -> 5 | Q10: =OFFSET(card_type!$A$1,MATCH(card!B10,card_type!B:B,0)-1,0) -> 1001 | R10: 1 | S10: =ROUND(IF(R10=0,0,IF(R10=1,X10*$S$1,IF(R10=2,X10*$S$1*buff的资质计算!$E$2,IF(R10=3,X10*$S$1*buff的资质计算!$E$3,0)))),0)*0 -> 0 | T10: 1 | U10: =J10*10+K10 -> 11 | V10: =ROUND((OFFSET(卡牌辅助配置表!$O$1,MATCH(U10,卡牌辅助配置表!M:M,0)-1,0)+(N10-1)*OFFSET(卡牌辅助配置表!$P$1,MATCH(U10,卡牌辅助配置表!M:M,0)-1,0))*M10,2) -> 7.11 | W10: =ROUND(IF(R10=0,0,IF(R10=1,X10*$W$1,IF(R10=2,X10*$W$1*buff的资质计算!$E$2,IF(R10=3,X10*$W$1*buff的资质计算!$E$3,0)))),2) -> 1.2 | X10: =M10*($M$1+(J10-1)*$J$1+(K10-1)*$K$1)+G10+$J$1*(N10-1)/$N$1 -> 4 | Y10: =X10+H10 -> 4 | Z10: =Y10/M10 -> 4 | AA10: =OFFSET(卡牌辅助配置表!$AD$1,MATCH(AB10,卡牌辅助配置表!AB:AB,0)-1,0) -> 90 | AB10: =J10*1000+K10*100+N10 -> 1105 | AF10: =((Q10*1000+1)*10+1)&$AF$1 -> 10010011| | AJ10: =IF(AN10=0,0,IF(AL10=0,$AM$1&$AF$1&AM10&$AF$1&$AJ$1,AK10&$AF$1&AL10&$AF$1&$AJ$1&$AM$1&$AF$1&AM10&$AF$1&$AJ$1)) -> 400023|1500|; | AK10: =OFFSET([1]item_type!$A$1,MATCH(Q10,[1]item_type!$G:$G,0)-1,0) -> 301001 | AM10: =IF(B10=B11,OFFSET(卡牌辅助配置表!$AE$1,MATCH(AB10,卡牌辅助配置表!AB:AB,0),0),0) -> 1500 | AN10: =IF(B10=B11,A10+1,0) -> 1001006 | AP10: =IF(AC10=0,0,IF(AC10=12,0,OFFSET(effect!$N$1,MATCH(K10,effect!M:M,0)-1,0))) -> 0
A11: =Q11*1000+N11 -> 1001006 | B11: 红玉指 | C11: 1 | D11: 6 | E11: 造成%d点%s拳法伤害 | G11: -3 | H11: =IF(R11=0,Y11,0) -> 0 | J11: =OFFSET(card_type!$F$1,MATCH(Q11,card_type!A:A,0)-1,0) -> 1 | K11: =OFFSET(card_type!$G$1,MATCH(Q11,card_type!A:A,0)-1,0) -> 1 | L11: 1 | M11: 1 | N11: =IF(B10=B11,N10+1,1) -> 6 | Q11: =OFFSET(card_type!$A$1,MATCH(card!B11,card_type!B:B,0)-1,0) -> 1001 | R11: 1 | S11: =ROUND(IF(R11=0,0,IF(R11=1,X11*$S$1,IF(R11=2,X11*$S$1*buff的资质计算!$E$2,IF(R11=3,X11*$S$1*buff的资质计算!$E$3,0)))),0)*0 -> 0 | T11: 1 | U11: =J11*10+K11 -> 11 | V11: =ROUND((OFFSET(卡牌辅助配置表!$O$1,MATCH(U11,卡牌辅助配置表!M:M,0)-1,0)+(N11-1)*OFFSET(卡牌辅助配置表!$P$1,MATCH(U11,卡牌辅助配置表!M:M,0)-1,0))*M11,2) -> 7.32 | W11: =ROUND(IF(R11=0,0,IF(R11=1,X11*$W$1,IF(R11=2,X11*$W$1*buff的资质计算!$E$2,IF(R11=3,X11*$W$1*buff的资质计算!$E$3,0)))),2) -> 1.35 | X11: =M11*($M$1+(J11-1)*$J$1+(K11-1)*$K$1)+G11+$J$1*(N11-1)/$N$1 -> 4.5 | Y11: =X11+H11 -> 4.5 | Z11: =Y11/M11 -> 4.5 | AA11: =OFFSET(卡牌辅助配置表!$AD$1,MATCH(AB11,卡牌辅助配置表!AB:AB,0)-1,0) -> 108 | AB11: =J11*1000+K11*100+N11 -> 1106 | AF11: =((Q11*1000+1)*10+1)&$AF$1 -> 10010011| | AJ11: =IF(AN11=0,0,IF(AL11=0,$AM$1&$AF$1&AM11&$AF$1&$AJ$1,AK11&$AF$1&AL11&$AF$1&$AJ$1&$AM$1&$AF$1&AM11&$AF$1&$AJ$1)) -> 400023|1700|; | AK11: =OFFSET([1]item_type!$A$1,MATCH(Q11,[1]item_type!$G:$G,0)-1,0) -> 301001 | AM11: =IF(B11=B12,OFFSET(卡牌辅助配置表!$AE$1,MATCH(AB11,卡牌辅助配置表!AB:AB,0),0),0) -> 1700 | AN11: =IF(B11=B12,A11+1,0) -> 1001007 | AP11: =IF(AC11=0,0,IF(AC11=12,0,OFFSET(effect!$N$1,MATCH(K11,effect!M:M,0)-1,0))) -> 0
A12: =Q12*1000+N12 -> 1001007 | B12: 红玉指 | C12: 1 | D12: 6 | E12: 造成%d点%s拳法伤害 | G12: -3 | H12: =IF(R12=0,Y12,0) -> 0 | J12: =OFFSET(card_type!$F$1,MATCH(Q12,card_type!A:A,0)-1,0) -> 1 | K12: =OFFSET(card_type!$G$1,MATCH(Q12,card_type!A:A,0)-1,0) -> 1 | L12: 1 | M12: 1 | N12: =IF(B11=B12,N11+1,1) -> 7 | Q12: =OFFSET(card_type!$A$1,MATCH(card!B12,card_type!B:B,0)-1,0) -> 1001 | R12: 1 | S12: =ROUND(IF(R12=0,0,IF(R12=1,X12*$S$1,IF(R12=2,X12*$S$1*buff的资质计算!$E$2,IF(R12=3,X12*$S$1*buff的资质计算!$E$3,0)))),0)*0 -> 0 | T12: 1 | U12: =J12*10+K12 -> 11 | V12: =ROUND((OFFSET(卡牌辅助配置表!$O$1,MATCH(U12,卡牌辅助配置表!M:M,0)-1,0)+(N12-1)*OFFSET(卡牌辅助配置表!$P$1,MATCH(U12,卡牌辅助配置表!M:M,0)-1,0))*M12,2) -> 7.52 | W12: =ROUND(IF(R12=0,0,IF(R12=1,X12*$W$1,IF(R12=2,X12*$W$1*buff的资质计算!$E$2,IF(R12=3,X12*$W$1*buff的资质计算!$E$3,0)))),2) -> 1.5 | X12: =M12*($M$1+(J12-1)*$J$1+(K12-1)*$K$1)+G12+$J$1*(N12-1)/$N$1 -> 5 | Y12: =X12+H12 -> 5 | Z12: =Y12/M12 -> 5 | AA12: =OFFSET(卡牌辅助配置表!$AD$1,MATCH(AB12,卡牌辅助配置表!AB:AB,0)-1,0) -> 126 | AB12: =J12*1000+K12*100+N12 -> 1107 | AF12: =((Q12*1000+1)*10+1)&$AF$1 -> 10010011| | AJ12: =IF(AN12=0,0,IF(AL12=0,$AM$1&$AF$1&AM12&$AF$1&$AJ$1,AK12&$AF$1&AL12&$AF$1&$AJ$1&$AM$1&$AF$1&AM12&$AF$1&$AJ$1)) -> 400023|1900|; | AK12: =OFFSET([1]item_type!$A$1,MATCH(Q12,[1]item_type!$G:$G,0)-1,0) -> 301001 | AM12: =IF(B12=B13,OFFSET(卡牌辅助配置表!$AE$1,MATCH(AB12,卡牌辅助配置表!AB:AB,0),0),0) -> 1900 | AN12: =IF(B12=B13,A12+1,0) -> 1001008 | AP12: =IF(AC12=0,0,IF(AC12=12,0,OFFSET(effect!$N$1,MATCH(K12,effect!M:M,0)-1,0))) -> 0
A13: =Q13*1000+N13 -> 1001008 | B13: 红玉指 | C13: 1 | D13: 6 | E13: 造成%d点%s拳法伤害 | G13: -3 | H13: =IF(R13=0,Y13,0) -> 0 | J13: =OFFSET(card_type!$F$1,MATCH(Q13,card_type!A:A,0)-1,0) -> 1 | K13: =OFFSET(card_type!$G$1,MATCH(Q13,card_type!A:A,0)-1,0) -> 1 | L13: 1 | M13: 1 | N13: =IF(B12=B13,N12+1,1) -> 8 | Q13: =OFFSET(card_type!$A$1,MATCH(card!B13,card_type!B:B,0)-1,0) -> 1001 | R13: 1 | S13: =ROUND(IF(R13=0,0,IF(R13=1,X13*$S$1,IF(R13=2,X13*$S$1*buff的资质计算!$E$2,IF(R13=3,X13*$S$1*buff的资质计算!$E$3,0)))),0)*0 -> 0 | T13: 1 | U13: =J13*10+K13 -> 11 | V13: =ROUND((OFFSET(卡牌辅助配置表!$O$1,MATCH(U13,卡牌辅助配置表!M:M,0)-1,0)+(N13-1)*OFFSET(卡牌辅助配置表!$P$1,MATCH(U13,卡牌辅助配置表!M:M,0)-1,0))*M13,2) -> 7.73 | W13: =ROUND(IF(R13=0,0,IF(R13=1,X13*$W$1,IF(R13=2,X13*$W$1*buff的资质计算!$E$2,IF(R13=3,X13*$W$1*buff的资质计算!$E$3,0)))),2) -> 1.65 | X13: =M13*($M$1+(J13-1)*$J$1+(K13-1)*$K$1)+G13+$J$1*(N13-1)/$N$1 -> 5.5 | Y13: =X13+H13 -> 5.5 | Z13: =Y13/M13 -> 5.5 | AA13: =OFFSET(卡牌辅助配置表!$AD$1,MATCH(AB13,卡牌辅助配置表!AB:AB,0)-1,0) -> 144 | AB13: =J13*1000+K13*100+N13 -> 1108 | AF13: =((Q13*1000+1)*10+1)&$AF$1 -> 10010011| | AJ13: =IF(AN13=0,0,IF(AL13=0,$AM$1&$AF$1&AM13&$AF$1&$AJ$1,AK13&$AF$1&AL13&$AF$1&$AJ$1&$AM$1&$AF$1&AM13&$AF$1&$AJ$1)) -> 400023|2100|; | AK13: =OFFSET([1]item_type!$A$1,MATCH(Q13,[1]item_type!$G:$G,0)-1,0) -> 301001 | AM13: =IF(B13=B14,OFFSET(卡牌辅助配置表!$AE$1,MATCH(AB13,卡牌辅助配置表!AB:AB,0),0),0) -> 2100 | AN13: =IF(B13=B14,A13+1,0) -> 1001009 | AP13: =IF(AC13=0,0,IF(AC13=12,0,OFFSET(effect!$N$1,MATCH(K13,effect!M:M,0)-1,0))) -> 0
A14: =Q14*1000+N14 -> 1001009 | B14: 红玉指 | C14: 1 | D14: 6 | E14: 造成%d点%s拳法伤害 | G14: -3 | H14: =IF(R14=0,Y14,0) -> 0 | J14: =OFFSET(card_type!$F$1,MATCH(Q14,card_type!A:A,0)-1,0) -> 1 | K14: =OFFSET(card_type!$G$1,MATCH(Q14,card_type!A:A,0)-1,0) -> 1 | L14: 1 | M14: 1 | N14: =IF(B13=B14,N13+1,1) -> 9 | Q14: =OFFSET(card_type!$A$1,MATCH(card!B14,card_type!B:B,0)-1,0) -> 1001 | R14: 1 | S14: =ROUND(IF(R14=0,0,IF(R14=1,X14*$S$1,IF(R14=2,X14*$S$1*buff的资质计算!$E$2,IF(R14=3,X14*$S$1*buff的资质计算!$E$3,0)))),0)*0 -> 0 | T14: 1 | U14: =J14*10+K14 -> 11 | V14: =ROUND((OFFSET(卡牌辅助配置表!$O$1,MATCH(U14,卡牌辅助配置表!M:M,0)-1,0)+(N14-1)*OFFSET(卡牌辅助配置表!$P$1,MATCH(U14,卡牌辅助配置表!M:M,0)-1,0))*M14,2) -> 7.94 | W14: =ROUND(IF(R14=0,0,IF(R14=1,X14*$W$1,IF(R14=2,X14*$W$1*buff的资质计算!$E$2,IF(R14=3,X14*$W$1*buff的资质计算!$E$3,0)))),2) -> 1.8 | X14: =M14*($M$1+(J14-1)*$J$1+(K14-1)*$K$1)+G14+$J$1*(N14-1)/$N$1 -> 6 | Y14: =X14+H14 -> 6 | Z14: =Y14/M14 -> 6 | AA14: =OFFSET(卡牌辅助配置表!$AD$1,MATCH(AB14,卡牌辅助配置表!AB:AB,0)-1,0) -> 162 | AB14: =J14*1000+K14*100+N14 -> 1109 | AF14: =((Q14*1000+1)*10+1)&$AF$1 -> 10010011| | AJ14: =IF(AN14=0,0,IF(AL14=0,$AM$1&$AF$1&AM14&$AF$1&$AJ$1,AK14&$AF$1&AL14&$AF$1&$AJ$1&$AM$1&$AF$1&AM14&$AF$1&$AJ$1)) -> 301001|15|;400023|2300|; | AK14: =OFFSET([1]item_type!$A$1,MATCH(Q14,[1]item_type!$G:$G,0)-1,0) -> 301001 | AL14: 15 | AM14: =IF(B14=B15,OFFSET(卡牌辅助配置表!$AE$1,MATCH(AB14,卡牌辅助配置表!AB:AB,0),0),0) -> 2300 | AN14: =IF(B14=B15,A14+1,0) -> 1001010 | AP14: =IF(AC14=0,0,IF(AC14=12,0,OFFSET(effect!$N$1,MATCH(K14,effect!M:M,0)-1,0))) -> 0
A15: =Q15*1000+N15 -> 1001010 | B15: 红玉指 | C15: 1 | D15: 6 | E15: 造成%d点%s拳法伤害 | G15: -3 | H15: =IF(R15=0,Y15,0) -> 0 | J15: =OFFSET(card_type!$F$1,MATCH(Q15,card_type!A:A,0)-1,0) -> 1 | K15: =OFFSET(card_type!$G$1,MATCH(Q15,card_type!A:A,0)-1,0) -> 1 | L15: 1 | M15: 1 | N15: =IF(B14=B15,N14+1,1) -> 10 | Q15: =OFFSET(card_type!$A$1,MATCH(card!B15,card_type!B:B,0)-1,0) -> 1001 | R15: 1 | S15: =ROUND(IF(R15=0,0,IF(R15=1,X15*$S$1,IF(R15=2,X15*$S$1*buff的资质计算!$E$2,IF(R15=3,X15*$S$1*buff的资质计算!$E$3,0)))),0)*0 -> 0 | T15: 1 | U15: =J15*10+K15 -> 11 | V15: =ROUND((OFFSET(卡牌辅助配置表!$O$1,MATCH(U15,卡牌辅助配置表!M:M,0)-1,0)+(N15-1)*OFFSET(卡牌辅助配置表!$P$1,MATCH(U15,卡牌辅助配置表!M:M,0)-1,0))*M15,2) -> 8.15 | W15: =ROUND(IF(R15=0,0,IF(R15=1,X15*$W$1,IF(R15=2,X15*$W$1*buff的资质计算!$E$2,IF(R15=3,X15*$W$1*buff的资质计算!$E$3,0)))),2) -> 1.95 | X15: =M15*($M$1+(J15-1)*$J$1+(K15-1)*$K$1)+G15+$J$1*(N15-1)/$N$1 -> 6.5 | Y15: =X15+H15 -> 6.5 | Z15: =Y15/M15 -> 6.5 | AA15: =OFFSET(卡牌辅助配置表!$AD$1,MATCH(AB15,卡牌辅助配置表!AB:AB,0)-1,0) -> 180 | AB15: =J15*1000+K15*100+N15 -> 1110 | AF15: =((Q15*1000+1)*10+1)&$AF$1 -> 10010011| | AJ15: =IF(AN15=0,0,IF(AL15=0,$AM$1&$AF$1&AM15&$AF$1&$AJ$1,AK15&$AF$1&AL15&$AF$1&$AJ$1&$AM$1&$AF$1&AM15&$AF$1&$AJ$1)) -> 400023|2700|; | AK15: =OFFSET([1]item_type!$A$1,MATCH(Q15,[1]item_type!$G:$G,0)-1,0) -> 301001 | AM15: =IF(B15=B16,OFFSET(卡牌辅助配置表!$AE$1,MATCH(AB15,卡牌辅助配置表!AB:AB,0),0),0) -> 2700 | AN15: =IF(B15=B16,A15+1,0) -> 1001011 | AP15: =IF(AC15=0,0,IF(AC15=12,0,OFFSET(effect!$N$1,MATCH(K15,effect!M:M,0)-1,0))) -> 0
A16: =Q16*1000+N16 -> 1001011 | B16: 红玉指 | C16: 1 | D16: 6 | E16: 造成%d点%s拳法伤害 | G16: -3 | H16: =IF(R16=0,Y16,0) -> 0 | J16: =OFFSET(card_type!$F$1,MATCH(Q16,card_type!A:A,0)-1,0) -> 1 | K16: =OFFSET(card_type!$G$1,MATCH(Q16,card_type!A:A,0)-1,0) -> 1 | L16: 1 | M16: 1 | N16: =IF(B15=B16,N15+1,1) -> 11 | Q16: =OFFSET(card_type!$A$1,MATCH(card!B16,card_type!B:B,0)-1,0) -> 1001 | R16: 1 | S16: =ROUND(IF(R16=0,0,IF(R16=1,X16*$S$1,IF(R16=2,X16*$S$1*buff的资质计算!$E$2,IF(R16=3,X16*$S$1*buff的资质计算!$E$3,0)))),0)*0 -> 0 | T16: 1 | U16: =J16*10+K16 -> 11 | V16: =ROUND((OFFSET(卡牌辅助配置表!$O$1,MATCH(U16,卡牌辅助配置表!M:M,0)-1,0)+(N16-1)*OFFSET(卡牌辅助配置表!$P$1,MATCH(U16,卡牌辅助配置表!M:M,0)-1,0))*M16,2) -> 8.36 | W16: =ROUND(IF(R16=0,0,IF(R16=1,X16*$W$1,IF(R16=2,X16*$W$1*buff的资质计算!$E$2,IF(R16=3,X16*$W$1*buff的资质计算!$E$3,0)))),2) -> 2.1 | X16: =M16*($M$1+(J16-1)*$J$1+(K16-1)*$K$1)+G16+$J$1*(N16-1)/$N$1 -> 7 | Y16: =X16+H16 -> 7 | Z16: =Y16/M16 -> 7 | AA16: =OFFSET(卡牌辅助配置表!$AD$1,MATCH(AB16,卡牌辅助配置表!AB:AB,0)-1,0) -> 207 | AB16: =J16*1000+K16*100+N16 -> 1111 | AF16: =((Q16*1000+1)*10+1)&$AF$1 -> 10010011| | AJ16: =IF(AN16=0,0,IF(AL16=0,$AM$1&$AF$1&AM16&$AF$1&$AJ$1,AK16&$AF$1&AL16&$AF$1&$AJ$1&$AM$1&$AF$1&AM16&$AF$1&$AJ$1)) -> 400023|3100|; | AK16: =OFFSET([1]item_type!$A$1,MATCH(Q16,[1]item_type!$G:$G,0)-1,0) -> 301001 | AM16: =IF(B16=B17,OFFSET(卡牌辅助配置表!$AE$1,MATCH(AB16,卡牌辅助配置表!AB:AB,0),0),0) -> 3100 | AN16: =IF(B16=B17,A16+1,0) -> 1001012 | AP16: =IF(AC16=0,0,IF(AC16=12,0,OFFSET(effect!$N$1,MATCH(K16,effect!M:M,0)-1,0))) -> 0
A17: =Q17*1000+N17 -> 1001012 | B17: 红玉指 | C17: 1 | D17: 6 | E17: 造成%d点%s拳法伤害 | G17: -3 | H17: =IF(R17=0,Y17,0) -> 0 | J17: =OFFSET(card_type!$F$1,MATCH(Q17,card_type!A:A,0)-1,0) -> 1 | K17: =OFFSET(card_type!$G$1,MATCH(Q17,card_type!A:A,0)-1,0) -> 1 | L17: 1 | M17: 1 | N17: =IF(B16=B17,N16+1,1) -> 12 | Q17: =OFFSET(card_type!$A$1,MATCH(card!B17,card_type!B:B,0)-1,0) -> 1001 | R17: 1 | S17: =ROUND(IF(R17=0,0,IF(R17=1,X17*$S$1,IF(R17=2,X17*$S$1*buff的资质计算!$E$2,IF(R17=3,X17*$S$1*buff的资质计算!$E$3,0)))),0)*0 -> 0 | T17: 1 | U17: =J17*10+K17 -> 11 | V17: =ROUND((OFFSET(卡牌辅助配置表!$O$1,MATCH(U17,卡牌辅助配置表!M:M,0)-1,0)+(N17-1)*OFFSET(卡牌辅助配置表!$P$1,MATCH(U17,卡牌辅助配置表!M:M,0)-1,0))*M17,2) -> 8.57 | W17: =ROUND(IF(R17=0,0,IF(R17=1,X17*$W$1,IF(R17=2,X17*$W$1*buff的资质计算!$E$2,IF(R17=3,X17*$W$1*buff的资质计算!$E$3,0)))),2) -> 2.25 | X17: =M17*($M$1+(J17-1)*$J$1+(K17-1)*$K$1)+G17+$J$1*(N17-1)/$N$1 -> 7.5 | Y17: =X17+H17 -> 7.5 | Z17: =Y17/M17 -> 7.5 | AA17: =OFFSET(卡牌辅助配置表!$AD$1,MATCH(AB17,卡牌辅助配置表!AB:AB,0)-1,0) -> 234 | AB17: =J17*1000+K17*100+N17 -> 1112 | AF17: =((Q17*1000+1)*10+1)&$AF$1 -> 10010011| | AJ17: =IF(AN17=0,0,IF(AL17=0,$AM$1&$AF$1&AM17&$AF$1&$AJ$1,AK17&$AF$1&AL17&$AF$1&$AJ$1&$AM$1&$AF$1&AM17&$AF$1&$AJ$1)) -> 400023|3500|; | AK17: =OFFSET([1]item_type!$A$1,MATCH(Q17,[1]item_type!$G:$G,0)-1,0) -> 301001 | AM17: =IF(B17=B18,OFFSET(卡牌辅助配置表!$AE$1,MATCH(AB17,卡牌辅助配置表!AB:AB,0),0),0) -> 3500 | AN17: =IF(B17=B18,A17+1,0) -> 1001013 | AP17: =IF(AC17=0,0,IF(AC17=12,0,OFFSET(effect!$N$1,MATCH(K17,effect!M:M,0)-1,0))) -> 0
A18: =Q18*1000+N18 -> 1001013 | B18: 红玉指 | C18: 1 | D18: 6 | E18: 造成%d点%s拳法伤害 | G18: -3 | H18: =IF(R18=0,Y18,0) -> 0 | J18: =OFFSET(card_type!$F$1,MATCH(Q18,card_type!A:A,0)-1,0) -> 1 | K18: =OFFSET(card_type!$G$1,MATCH(Q18,card_type!A:A,0)-1,0) -> 1 | L18: 1 | M18: 1 | N18: =IF(B17=B18,N17+1,1) -> 13 | Q18: =OFFSET(card_type!$A$1,MATCH(card!B18,card_type!B:B,0)-1,0) -> 1001 | R18: 1 | S18: =ROUND(IF(R18=0,0,IF(R18=1,X18*$S$1,IF(R18=2,X18*$S$1*buff的资质计算!$E$2,IF(R18=3,X18*$S$1*buff的资质计算!$E$3,0)))),0)*0 -> 0 | T18: 1 | U18: =J18*10+K18 -> 11 | V18: =ROUND((OFFSET(卡牌辅助配置表!$O$1,MATCH(U18,卡牌辅助配置表!M:M,0)-1,0)+(N18-1)*OFFSET(卡牌辅助配置表!$P$1,MATCH(U18,卡牌辅助配置表!M:M,0)-1,0))*M18,2) -> 8.78 | W18: =ROUND(IF(R18=0,0,IF(R18=1,X18*$W$1,IF(R18=2,X18*$W$1*buff的资质计算!$E$2,IF(R18=3,X18*$W$1*buff的资质计算!$E$3,0)))),2) -> 2.4 | X18: =M18*($M$1+(J18-1)*$J$1+(K18-1)*$K$1)+G18+$J$1*(N18-1)/$N$1 -> 8 | Y18: =X18+H18 -> 8 | Z18: =Y18/M18 -> 8 | AA18: =OFFSET(卡牌辅助配置表!$AD$1,MATCH(AB18,卡牌辅助配置表!AB:AB,0)-1,0) -> 261 | AB18: =J18*1000+K18*100+N18 -> 1113 | AF18: =((Q18*1000+1)*10+1)&$AF$1 -> 10010011| | AJ18: =IF(AN18=0,0,IF(AL18=0,$AM$1&$AF$1&AM18&$AF$1&$AJ$1,AK18&$AF$1&AL18&$AF$1&$AJ$1&$AM$1&$AF$1&AM18&$AF$1&$AJ$1)) -> 400023|3900|; | AK18: =OFFSET([1]item_type!$A$1,MATCH(Q18,[1]item_type!$G:$G,0)-1,0) -> 301001 | AM18: =IF(B18=B19,OFFSET(卡牌辅助配置表!$AE$1,MATCH(AB18,卡牌辅助配置表!AB:AB,0),0),0) -> 3900 | AN18: =IF(B18=B19,A18+1,0) -> 1001014 | AP18: =IF(AC18=0,0,IF(AC18=12,0,OFFSET(effect!$N$1,MATCH(K18,effect!M:M,0)-1,0))) -> 0
A19: =Q19*1000+N19 -> 1001014 | B19: 红玉指 | C19: 1 | D19: 6 | E19: 造成%d点%s拳法伤害 | G19: -3 | H19: =IF(R19=0,Y19,0) -> 0 | J19: =OFFSET(card_type!$F$1,MATCH(Q19,card_type!A:A,0)-1,0) -> 1 | K19: =OFFSET(card_type!$G$1,MATCH(Q19,card_type!A:A,0)-1,0) -> 1 | L19: 1 | M19: 1 | N19: =IF(B18=B19,N18+1,1) -> 14 | Q19: =OFFSET(card_type!$A$1,MATCH(card!B19,card_type!B:B,0)-1,0) -> 1001 | R19: 1 | S19: =ROUND(IF(R19=0,0,IF(R19=1,X19*$S$1,IF(R19=2,X19*$S$1*buff的资质计算!$E$2,IF(R19=3,X19*$S$1*buff的资质计算!$E$3,0)))),0)*0 -> 0 | T19: 1 | U19: =J19*10+K19 -> 11 | V19: =ROUND((OFFSET(卡牌辅助配置表!$O$1,MATCH(U19,卡牌辅助配置表!M:M,0)-1,0)+(N19-1)*OFFSET(卡牌辅助配置表!$P$1,MATCH(U19,卡牌辅助配置表!M:M,0)-1,0))*M19,2) -> 8.99 | W19: =ROUND(IF(R19=0,0,IF(R19=1,X19*$W$1,IF(R19=2,X19*$W$1*buff的资质计算!$E$2,IF(R19=3,X19*$W$1*buff的资质计算!$E$3,0)))),2) -> 2.55 | X19: =M19*($M$1+(J19-1)*$J$1+(K19-1)*$K$1)+G19+$J$1*(N19-1)/$N$1 -> 8.5 | Y19: =X19+H19 -> 8.5 | Z19: =Y19/M19 -> 8.5 | AA19: =OFFSET(卡牌辅助配置表!$AD$1,MATCH(AB19,卡牌辅助配置表!AB:AB,0)-1,0) -> 288 | AB19: =J19*1000+K19*100+N19 -> 1114 | AF19: =((Q19*1000+1)*10+1)&$AF$1 -> 10010011| | AJ19: =IF(AN19=0,0,IF(AL19=0,$AM$1&$AF$1&AM19&$AF$1&$AJ$1,AK19&$AF$1&AL19&$AF$1&$AJ$1&$AM$1&$AF$1&AM19&$AF$1&$AJ$1)) -> 400023|4300|; | AK19: =OFFSET([1]item_type!$A$1,MATCH(Q19,[1]item_type!$G:$G,0)-1,0) -> 301001 | AM19: =IF(B19=B20,OFFSET(卡牌辅助配置表!$AE$1,MATCH(AB19,卡牌辅助配置表!AB:AB,0),0),0) -> 4300 | AN19: =IF(B19=B20,A19+1,0) -> 1001015 | AP19: =IF(AC19=0,0,IF(AC19=12,0,OFFSET(effect!$N$1,MATCH(K19,effect!M:M,0)-1,0))) -> 0
A20: =Q20*1000+N20 -> 1001015 | B20: 红玉指 | C20: 1 | D20: 6 | E20: 造成%d点%s拳法伤害 | G20: -3 | H20: =IF(R20=0,Y20,0) -> 0 | J20: =OFFSET(card_type!$F$1,MATCH(Q20,card_type!A:A,0)-1,0) -> 1 | K20: =OFFSET(card_type!$G$1,MATCH(Q20,card_type!A:A,0)-1,0) -> 1 | L20: 1 | M20: 1 | N20: =IF(B19=B20,N19+1,1) -> 15 | Q20: =OFFSET(card_type!$A$1,MATCH(card!B20,card_type!B:B,0)-1,0) -> 1001 | R20: 1 | S20: =ROUND(IF(R20=0,0,IF(R20=1,X20*$S$1,IF(R20=2,X20*$S$1*buff的资质计算!$E$2,IF(R20=3,X20*$S$1*buff的资质计算!$E$3,0)))),0)*0 -> 0 | T20: 1 | U20: =J20*10+K20 -> 11 | V20: =ROUND((OFFSET(卡牌辅助配置表!$O$1,MATCH(U20,卡牌辅助配置表!M:M,0)-1,0)+(N20-1)*OFFSET(卡牌辅助配置表!$P$1,MATCH(U20,卡牌辅助配置表!M:M,0)-1,0))*M20,2) -> 9.2 | W20: =ROUND(IF(R20=0,0,IF(R20=1,X20*$W$1,IF(R20=2,X20*$W$1*buff的资质计算!$E$2,IF(R20=3,X20*$W$1*buff的资质计算!$E$3,0)))),2) -> 2.7 | X20: =M20*($M$1+(J20-1)*$J$1+(K20-1)*$K$1)+G20+$J$1*(N20-1)/$N$1 -> 9 | Y20: =X20+H20 -> 9 | Z20: =Y20/M20 -> 9 | AA20: =OFFSET(卡牌辅助配置表!$AD$1,MATCH(AB20,卡牌辅助配置表!AB:AB,0)-1,0) -> 315 | AB20: =J20*1000+K20*100+N20 -> 1115 | AF20: =((Q20*1000+1)*10+1)&$AF$1 -> 10010011| | AJ20: =IF(AN20=0,0,IF(AL20=0,$AM$1&$AF$1&AM20&$AF$1&$AJ$1,AK20&$AF$1&AL20&$AF$1&$AJ$1&$AM$1&$AF$1&AM20&$AF$1&$AJ$1)) -> 400023|4700|; | AK20: =OFFSET([1]item_type!$A$1,MATCH(Q20,[1]item_type!$G:$G,0)-1,0) -> 301001 | AM20: =IF(B20=B21,OFFSET(卡牌辅助配置表!$AE$1,MATCH(AB20,卡牌辅助配置表!AB:AB,0),0),0) -> 4700 | AN20: =IF(B20=B21,A20+1,0) -> 1001016 | AP20: =IF(AC20=0,0,IF(AC20=12,0,OFFSET(effect!$N$1,MATCH(K20,effect!M:M,0)-1,0))) -> 0
